Workbook
Name Art: #REF!
Name Art: #REF!
Name Art: #REF!
Name Art: #REF!
Name Art: #REF!
Name Art: #REF!
Name Art: #REF!
Name Art: #REF!
Name Art: #REF!
Name Art: #REF!
Name Art: #REF!
Name Art: #REF!
Name Art: #REF!
Name Art: #REF!
Name Art: #REF!
Name Art: #REF!
Name Art: #REF!
Name Art: #REF!
Name Art: #REF!
Name Art: #REF!
Name Art: #REF!
Name Art: #REF!
Name Art: #REF!
Name Art: #REF!
Name Art: #REF!
Name Art: #REF!
Name Art: #REF!
Name Art: #REF!
Name Art: #REF!
Name Art: #REF!
Name Art: #REF!
Name Art: #REF!
Name Art: #REF!
Name Art: #REF!
Name Art: #REF!
Name Art: #REF!
Name Art: #REF!
Name Art: #REF!
Name Art: #REF!
Name Art: #REF!
Name Art: #REF!
Name Art: #REF!
Name Art: #REF!
Name Art: #REF!
Name Art: #REF!
Name Art: #REF!
Name Art: #REF!
Name Art: #REF!
Name codart: #REF!
Name codart: #REF!
Name codart: #REF!
Name codart: #REF!
Name codart: #REF!
Name codart: #REF!
Name codart: #REF!
Name codart: #REF!
Name codart: #REF!
Name codart: #REF!
Name codart: #REF!
Name codart: #REF!

Sheet 361KP
A1: FOUR DESIGN (PVT.) LTD
A2: A 100% Export Oriented Knit Garments
A3: Plot # S - 7 & S - 8, BSCIC, I/E, Fatullah, Narayanganj.
A5: PACKING LIST
A7: BUYER | E7: : | F7: PACIFIC COLLECTIONS | U7: Date:
A8: ORDER NO | E8: : | F8: 53920
A9: ITEM CODE | E9: : | F9: 361KP
A10: ITEM NAME | E10: : | F10: Sheep Flash Mob
A11: ORDER QTY. | E11: : | F11: 1470
A12: SHIPPEPD QTY. | E12: : | F12: =M33 -> 1481
A13: EXCESS/SHORT QTY. | E13: : | F13: =F12-F11 -> 11
A14: CTN QTY. | E14: : | F14: =N29 -> 21
A15: FABRICATION | E15: : | F15: 100% Cotton, 150 GSM.
A17: CTN NO. | D17: COLOR | G17: SIZE | M17: PCS/CTN | N17: TOTAL CTN | O17: TOTAL QTY | P17: CTN MEAS. | S17: WEIGHT (KGS) | U17: WEIGHT (KGS)
G18: 2 | H18: 4 | I18: 6 | J18: 8 | K18: 10 | L18: 12 | P18: L | Q18: W | R18: H | S18: N.W. | T18: G.W | U18: TTL N.W | V18: TTL G.W
A19: 1 | B19: - | C19: =N19 -> 3 | D19: Opal Green | G19: 80 | M19: =SUM(G19:L19) -> 80 | N19: 3 | O19: =M19*N19 -> 240 | P19: 51 | Q19: 28 | R19: 22 | S19: 5.05 | T19: =S19+0.9 -> 5.95 | U19: =S19*N19 -> 15.15 | V19: =T19*N19 -> 17.85
A20: =C19+1 -> 4 | B20: - | C20: =C19+N20 -> 7 | H20: 80 | M20: =SUM(G20:L20) -> 80 | N20: 4 | O20: =M20*N20 -> 320 | S20: 5.7 | T20: =S20+0.9 -> 6.6 | U20: =S20*N20 -> 22.8 | V20: =T20*N20 -> 26.4
A21: =C20+1 -> 8 | B21: - | C21: =C20+N21 -> 12 | I21: 70 | M21: =SUM(G21:L21) -> 70 | N21: 5 | O21: =M21*N21 -> 350 | S21: 5.8 | T21: =S21+0.9 -> 6.7 | U21: =S21*N21 -> 29 | V21: =T21*N21 -> 33.5
A22: =C21+1 -> 13 | B22: - | C22: =C21+N22 -> 15 | J22: 70 | M22: =SUM(G22:L22) -> 70 | N22: 3 | O22: =M22*N22 -> 210 | S22: 6.5 | T22: =S22+0.9 -> 7.4 | U22: =S22*N22 -> 19.5 | V22: =T22*N22 -> 22.2
A23: =C22+1 -> 16 | B23: - | C23: =C22+N23 -> 18 | K23: 60 | M23: =SUM(G23:L23) -> 60 | N23: 3 | O23: =M23*N23 -> 180 | S23: 6.3 | T23: =S23+0.9 -> 7.2 | U23: =S23*N23 -> 18.9 | V23: =T23*N23 -> 21.6
A24: =C23+1 -> 19 | B24: - | C24: =C23+N24 -> 19 | G24: 65 | M24: =SUM(G24:L24) -> 65 | N24: 1 | O24: =M24*N24 -> 65 | S24: 4.1 | T24: =S24+0.9 -> 5 | U24: =S24*N24 -> 4.1 | V24: =T24*N24 -> 5
A25: =C24+1 -> 20 | B25: - | C25: =C24+N25 -> 20 | H25: 38 | J25: 38 | M25: =SUM(G25:L25) -> 76 | N25: 1 | O25: =M25*N25 -> 76 | S25: 6.25 | T25: =S25+0.9 -> 7.15 | U25: =S25*N25 -> 6.25 | V25: =T25*N25 -> 7.15
A26: =C25+1 -> 21 | B26: - | C26: =C25+N26 -> 21 | K26: 40 | M26: =SUM(G26:L26) -> 40 | N26: 1 | O26: =M26*N26 -> 40 | S26: 4.2 | T26: =S26+0.9 -> 5.1 | U26: =S26*N26 -> 4.2 | V26: =T26*N26 -> 5.1
A27: TOTAL | G27: =O19+G24 -> 305 | H27: =O20+H25 -> 358 | I27: =O21+I26 -> 350 | J27: =O22+J25 -> 248 | K27: =O23+K26 -> 220 | N27: =SUM(N19:N26) -> 21 | O27: =SUM(O19:O26) -> 1481 | P27: =(P19*Q19*R19)/1000000*N27 -> 0.659736 | U27: =SUM(U19:U26) -> 119.9 | V27: =SUM(V19:V26) -> 138.8
A29: GRAND TOTAL | N29: =N27 -> 21 | O29: =O27 -> 1481 | P29: =P27 -> 0.659736 | U29: =U27 -> 119.9 | V29: =V27 -> 138.8
A31: ORDER & SHIP QTY | D31: =D17 -> COLOR | G31: =G18 -> 2 | H31: =H18 -> 4 | I31: =I18 -> 6 | J31: =J18 -> 8 | K31: =K18 -> 10 | L31: =L18 -> 12 | M31: TOTAL
A32: ORDER QTY. | D32: =D19 -> Opal Green | G32: 300 | H32: 350 | I32: 350 | J32: 250 | K32: 220 | M32: =G32+H32+I32+J32+K32+L32 -> 1470
A33: SHIP QTY. | G33: =G27 -> 305 | H33: =H27 -> 358 | I33: =I27 -> 350 | J33: =J27 -> 248 | K33: =K27 -> 220 | M33: =G33+H33+I33+J33+K33+L33 -> 1481

Sheet 364KP
A1: FOUR DESIGN (PVT.) LTD
A2: A 100% Export Oriented Knit Garments
A3: Plot # S - 7 & S - 8, BSCIC, I/E, Fatullah, Narayanganj.
A5: PACKING LIST
A7: BUYER | E7: : | F7: PACIFIC COLLECTIONS | U7: Date:
A8: ORDER NO | E8: : | F8: 53920
A9: ITEM CODE | E9: : | F9: 364KP
A10: ITEM NAME | E10: : | F10: Kiwi Flash Mob
A11: ORDER QTY. | E11: : | F11: 1700
A12: SHIPPEPD QTY. | E12: : | F12: =M33 -> 1738
A13: EXCESS/SHORT QTY. | E13: : | F13: =F12-F11 -> 38
A14: CTN QTY. | E14: : | F14: =N29 -> 25
A15: FABRICATION | E15: : | F15: 100% Cotton, 150 GSM.
A17: CTN NO. | D17: COLOR | G17: SIZE | M17: PCS/CTN | N17: TOTAL CTN | O17: TOTAL QTY | P17: CTN MEAS. | S17: WEIGHT (KGS) | U17: WEIGHT (KGS)
G18: 2 | H18: 4 | I18: 6 | J18: 8 | K18: 10 | L18: 12 | P18: L | Q18: W | R18: H | S18: N.W. | T18: G.W | U18: TTL N.W | V18: TTL G.W
A19: 1 | B19: - | C19: =N19 -> 4 | D19: Sky Blue | G19: 80 | M19: =SUM(G19:L19) -> 80 | N19: 4 | O19: =M19*N19 -> 320 | P19: 51 | Q19: 28 | R19: 22 | S19: 5.1 | T19: =S19+0.9 -> 6 | U19: =S19*N19 -> 20.4 | V19: =T19*N19 -> 24
A20: =C19+1 -> 5 | B20: - | C20: =C19+N20 -> 7 | H20: 80 | M20: =SUM(G20:L20) -> 80 | N20: 3 | O20: =M20*N20 -> 240 | S20: 5.7 | T20: =S20+0.9 -> 6.6 | U20: =S20*N20 -> 17.1 | V20: =T20*N20 -> 19.8
A21: =C20+1 -> 8 | B21: - | C21: =C20+N21 -> 12 | I21: 70 | M21: =SUM(G21:L21) -> 70 | N21: 5 | O21: =M21*N21 -> 350 | S21: 5.8 | T21: =S21+0.9 -> 6.7 | U21: =S21*N21 -> 29 | V21: =T21*N21 -> 33.5
A22: =C21+1 -> 13 | B22: - | C22: =C21+N22 -> 17 | J22: 70 | M22: =SUM(G22:L22) -> 70 | N22: 5 | O22: =M22*N22 -> 350 | S22: 6.6 | T22: =S22+0.9 -> 7.5 | U22: =S22*N22 -> 33 | V22: =T22*N22 -> 37.5
A23: =C22+1 -> 18 | B23: - | C23: =C22+N23 -> 22 | K23: 60 | M23: =SUM(G23:L23) -> 60 | N23: 5 | O23: =M23*N23 -> 300 | S23: 6.4 | T23: =S23+0.9 -> 7.3 | U23: =S23*N23 -> 32 | V23: =T23*N23 -> 36.5
A24: =C23+1 -> 23 | B24: - | C24: =C23+N24 -> 23 | H24: 62 | M24: =SUM(G24:L24) -> 62 | N24: 1 | O24: =M24*N24 -> 62 | S24: 4.5 | T24: =S24+0.9 -> 5.4 | U24: =S24*N24 -> 4.5 | V24: =T24*N24 -> 5.4
A25: =C24+1 -> 24 | B25: - | C25: =C24+N25 -> 24 | I25: 62 | M25: =SUM(G25:L25) -> 62 | N25: 1 | O25: =M25*N25 -> 62 | S25: 5.1 | T25: =S25+0.9 -> 6 | U25: =S25*N25 -> 5.1 | V25: =T25*N25 -> 6
A26: =C25+1 -> 25 | B26: - | C26: =C25+N26 -> 25 | G26: 35 | J26: 13 | K26: 6 | M26: =SUM(G26:L26) -> 54 | N26: 1 | O26: =M26*N26 -> 54 | S26: 4.2 | T26: =S26+0.9 -> 5.1 | U26: =S26*N26 -> 4.2 | V26: =T26*N26 -> 5.1
A27: TOTAL | G27: =O19+G26 -> 355 | H27: =O20+H24 -> 302 | I27: =O21+I25 -> 412 | J27: =O22+J26 -> 363 | K27: =O23+K26 -> 306 | N27: =SUM(N19:N26) -> 25 | O27: =SUM(O19:O26) -> 1738 | P27: =(P19*Q19*R19)/1000000*N27 -> 0.7854 | U27: =SUM(U19:U26) -> 145.3 | V27: =SUM(V19:V26) -> 167.8
A29: GRAND TOTAL | N29: =N27 -> 25 | O29: =O27 -> 1738 | P29: =P27 -> 0.7854 | U29: =U27 -> 145.3 | V29: =V27 -> 167.8
A31: ORDER & SHIP QTY | D31: =D17 -> COLOR | G31: =G18 -> 2 | H31: =H18 -> 4 | I31: =I18 -> 6 | J31: =J18 -> 8 | K31: =K18 -> 10 | L31: =L18 -> 12 | M31: TOTAL
A32: ORDER QTY. | D32: =D19 -> Sky Blue | G32: 350 | H32: 300 | I32: 400 | J32: 350 | K32: 300 | M32: =G32+H32+I32+J32+K32+L32 -> 1700
A33: SHIP QTY. | G33: =G27 -> 355 | H33: =H27 -> 302 | I33: =I27 -> 412 | J33: =J27 -> 363 | K33: =K27 -> 306 | L33: =L27 -> 0 | M33: =G33+H33+I33+J33+K33+L33 -> 1738

Sheet 368KP
A1: FOUR DESIGN (PVT.) LTD
A2: A 100% Export Oriented Knit Garments
A3: Plot # S - 7 & S - 8, BSCIC, I/E, Fatullah, Narayanganj.
A5: PACKING LIST
A7: BUYER | E7: : | F7: PACIFIC COLLECTIONS | U7: Date:
A8: ORDER NO | E8: : | F8: 53920
A9: ITEM CODE | E9: : | F9: 368KP
A10: ITEM NAME | E10: : | F10: Floral Kiwi
A11: ORDER QTY. | E11: : | F11: 1500
A12: SHIPPEPD QTY. | E12: : | F12: =M32 -> 1531
A13: EXCESS/SHORT QTY. | E13: : | F13: =F12-F11 -> 31
A14: CTN QTY. | E14: : | F14: =N28 -> 21
A15: FABRICATION | E15: : | F15: 100% Cotton, 150 GSM.
A17: CTN NO. | D17: COLOR | G17: SIZE | M17: PCS/CTN | N17: TOTAL CTN | O17: TOTAL QTY | P17: CTN MEAS. | S17: WEIGHT (KGS) | U17: WEIGHT (KGS)
G18: 2 | H18: 4 | I18: 6 | J18: 8 | K18: 10 | L18: 12 | P18: L | Q18: W | R18: H | S18: N.W. | T18: G.W | U18: TTL N.W | V18: TTL G.W
A19: 1 | B19: - | C19: =N19 -> 3 | D19: Lilac | G19: 80 | M19: =SUM(G19:L19) -> 80 | N19: 3 | O19: =M19*N19 -> 240 | P19: 51 | Q19: 28 | R19: 22 | S19: 4.9 | T19: =S19+0.9 -> 5.8 | U19: =S19*N19 -> 14.7 | V19: =T19*N19 -> 17.4
A20: =C19+1 -> 4 | B20: - | C20: =C19+N20 -> 6 | H20: 80 | M20: =SUM(G20:L20) -> 80 | N20: 3 | O20: =M20*N20 -> 240 | S20: 5.35 | T20: =S20+0.9 -> 6.25 | U20: =S20*N20 -> 16.05 | V20: =T20*N20 -> 18.75
A21: =C20+1 -> 7 | B21: - | C21: =C20+N21 -> 11 | I21: 70 | M21: =SUM(G21:L21) -> 70 | N21: 5 | O21: =M21*N21 -> 350 | S21: 5.45 | T21: =S21+0.9 -> 6.35 | U21: =S21*N21 -> 27.25 | V21: =T21*N21 -> 31.75
A22: =C21+1 -> 12 | B22: - | C22: =C21+N22 -> 15 | J22: 70 | M22: =SUM(G22:L22) -> 70 | N22: 4 | O22: =M22*N22 -> 280 | S22: 6.3 | T22: =S22+0.9 -> 7.2 | U22: =S22*N22 -> 25.2 | V22: =T22*N22 -> 28.8
A23: =C22+1 -> 16 | B23: - | C23: =C22+N23 -> 19 | K23: 60 | M23: =SUM(G23:L23) -> 60 | N23: 4 | O23: =M23*N23 -> 240 | S23: 6.05 | T23: =S23+0.9 -> 6.95 | U23: =S23*N23 -> 24.2 | V23: =T23*N23 -> 27.8
A24: =C23+1 -> 20 | B24: - | C24: =C23+N24 -> 20 | H24: 63 | K24: 16 | M24: =SUM(G24:L24) -> 79 | N24: 1 | O24: =M24*N24 -> 79 | S24: 6.2 | T24: =S24+0.9 -> 7.1 | U24: =S24*N24 -> 6.2 | V24: =T24*N24 -> 7.1
A25: =C24+1 -> 21 | B25: - | C25: =C24+N25 -> 21 | G25: 65 | I25: 13 | J25: 24 | M25: =SUM(G25:L25) -> 102 | N25: 1 | O25: =M25*N25 -> 102 | S25: 7 | T25: =S25+0.9 -> 7.9 | U25: =S25*N25 -> 7 | V25: =T25*N25 -> 7.9
A26: TOTAL | G26: =O19+G25 -> 305 | H26: =O20+H24 -> 303 | I26: =O21+I25 -> 363 | J26: =O22+J25 -> 304 | K26: =O23+K24 -> 256 | N26: =SUM(N19:N25) -> 21 | O26: =SUM(O19:O25) -> 1531 | P26: =(P19*Q19*R19)/1000000*N26 -> 0.659736 | U26: =SUM(U19:U25) -> 120.6 | V26: =SUM(V19:V25) -> 139.5
A28: GRAND TOTAL | N28: =N26 -> 21 | O28: =O26 -> 1531 | P28: =P26 -> 0.659736 | U28: =U26 -> 120.6 | V28: =V26 -> 139.5
A30: ORDER & SHIP QTY | D30: =D17 -> COLOR | G30: =G18 -> 2 | H30: =H18 -> 4 | I30: =I18 -> 6 | J30: =J18 -> 8 | K30: =K18 -> 10 | L30: =L18 -> 12 | M30: TOTAL
A31: ORDER QTY. | D31: =D19 -> Lilac | G31: 300 | H31: 300 | I31: 350 | J31: 300 | K31: 250 | M31: =G31+H31+I31+J31+K31+L31 -> 1500
A32: SHIP QTY. | G32: =G26 -> 305 | H32: =H26 -> 303 | I32: =I26 -> 363 | J32: =J26 -> 304 | K32: =K26 -> 256 | M32: =G32+H32+I32+J32+K32+L32 -> 1531

Sheet 378KP
A1: FOUR DESIGN (PVT.) LTD
A2: A 100% Export Oriented Knit Garments
A3: Plot # S - 7 & S - 8, BSCIC, I/E, Fatullah, Narayanganj.
A5: PACKING LIST
A7: BUYER | E7: : | F7: PACIFIC COLLECTIONS | U7: Date:
A8: ORDER NO | E8: : | F8: 53920
A9: ITEM CODE | E9: : | F9: 378KP
A10: ITEM NAME | E10: : | F10: Kiwi Batik
A11: ORDER QTY. | E11: : | F11: 2150
A12: SHIPPEPD QTY. | E12: : | F12: =M33 -> 2181
A13: EXCESS/SHORT QTY. | E13: : | F13: =F12-F11 -> 31
A14: CTN QTY. | E14: : | F14: =N29 -> 31
A15: FABRICATION | E15: : | F15: 100% Cotton, 150 GSM.
A17: CTN NO. | D17: COLOR | G17: SIZE | M17: PCS/CTN | N17: TOTAL CTN | O17: TOTAL QTY | P17: CTN MEAS. | S17: WEIGHT (KGS) | U17: WEIGHT (KGS)
G18: 2 | H18: 4 | I18: 6 | J18: 8 | K18: 10 | L18: 12 | P18: L | Q18: W | R18: H | S18: N.W. | T18: G.W | U18: TTL N.W | V18: TTL G.W
A19: 1 | B19: - | C19: =N19 -> 4 | D19: Hot Pink | G19: 80 | M19: =SUM(G19:L19) -> 80 | N19: 4 | O19: =M19*N19 -> 320 | P19: 51 | Q19: 28 | R19: 22 | S19: 5.1 | T19: =S19+0.9 -> 6 | U19: =S19*N19 -> 20.4 | V19: =T19*N19 -> 24
A20: =C19+1 -> 5 | B20: - | C20: =C19+N20 -> 9 | H20: 80 | M20: =SUM(G20:L20) -> 80 | N20: 5 | O20: =M20*N20 -> 400 | S20: 5.7 | T20: =S20+0.9 -> 6.6 | U20: =S20*N20 -> 28.5 | V20: =T20*N20 -> 33
A21: =C20+1 -> 10 | B21: - | C21: =C20+N21 -> 13 | I21: 70 | M21: =SUM(G21:L21) -> 70 | N21: 4 | O21: =M21*N21 -> 280 | S21: 5.8 | T21: =S21+0.9 -> 6.7 | U21: =S21*N21 -> 23.2 | V21: =T21*N21 -> 26.8
A22: =C21+1 -> 14 | B22: - | C22: =C21+N22 -> 18 | J22: 70 | M22: =SUM(G22:L22) -> 70 | N22: 5 | O22: =M22*N22 -> 350 | S22: 6.6 | T22: =S22+0.9 -> 7.5 | U22: =S22*N22 -> 33 | V22: =T22*N22 -> 37.5
A23: =C22+1 -> 19 | B23: - | C23: =C22+N23 -> 24 | K23: 60 | M23: =SUM(G23:L23) -> 60 | N23: 6 | O23: =M23*N23 -> 360 | S23: 6.4 | T23: =S23+0.9 -> 7.3 | U23: =S23*N23 -> 38.4 | V23: =T23*N23 -> 43.8
A24: =C23+1 -> 25 | B24: - | C24: =C23+N24 -> 29 | L24: 60 | M24: =SUM(G24:L24) -> 60 | N24: 5 | O24: =M24*N24 -> 300 | S24: 6.3 | T24: =S24+0.9 -> 7.2 | U24: =S24*N24 -> 31.5 | V24: =T24*N24 -> 36
A25: =C24+1 -> 30 | B25: - | C25: =C24+N25 -> 30 | G25: 15 | H25: 48 | J25: 25 | L25: 8 | M25: =SUM(G25:L25) -> 96 | N25: 1 | O25: =M25*N25 -> 96 | S25: 7.1 | T25: =S25+0.9 -> 8 | U25: =S25*N25 -> 7.1 | V25: =T25*N25 -> 8
A26: =C25+1 -> 31 | B26: - | C26: =C25+N26 -> 31 | I26: 27 | K26: 48 | M26: =SUM(G26:L26) -> 75 | N26: 1 | O26: =M26*N26 -> 75 | S26: 6.5 | T26: =S26+0.9 -> 7.4 | U26: =S26*N26 -> 6.5 | V26: =T26*N26 -> 7.4
A27: TOTAL | G27: =O19+G25 -> 335 | H27: =O20+H25 -> 448 | I27: =O21+I26 -> 307 | J27: =O22+J25 -> 375 | K27: =O23+K26 -> 408 | L27: =O24+L25 -> 308 | N27: =SUM(N19:N26) -> 31 | O27: =SUM(O19:O26) -> 2181 | P27: =(P19*Q19*R19)/1000000*N27 -> 0.973896 | U27: =SUM(U19:U26) -> 188.6 | V27: =SUM(V19:V26) -> 216.5
A29: GRAND TOTAL | N29: =N27 -> 31 | O29: =O27 -> 2181 | P29: =P27 -> 0.973896 | U29: =U27 -> 188.6 | V29: =V27 -> 216.5
A31: ORDER & SHIP QTY | D31: =D17 -> COLOR | G31: =G18 -> 2 | H31: =H18 -> 4 | I31: =I18 -> 6 | J31: =J18 -> 8 | K31: =K18 -> 10 | L31: =L18 -> 12 | M31: TOTAL
A32: ORDER QTY. | D32: =D19 -> Hot Pink | G32: 350 | H32: 450 | I32: 300 | J32: 350 | K32: 400 | L32: 300 | M32: =G32+H32+I32+J32+K32+L32 -> 2150
A33: SHIP QTY. | G33: =G27 -> 335 | H33: =H27 -> 448 | I33: =I27 -> 307 | J33: =J27 -> 375 | K33: =K27 -> 408 | L33: =L27 -> 308 | M33: =G33+H33+I33+J33+K33+L33 -> 2181

Sheet 682WK
A1: FOUR DESIGN (PVT.) LTD
A2: A 100% Export Oriented Knit Garments
A3: Plot # S - 7 & S - 8, BSCIC, I/E, Fatullah, Narayanganj.
A5: PACKING LIST
A7: BUYER | E7: : | F7: PACIFIC COLLECTIONS | U7: Date:
A8: ORDER NO | E8: : | F8: 53920
A9: ITEM CODE | E9: : | F9: 682WK
A10: ITEM NAME | E10: : | F10: Paddle birding
A11: ORDER QTY. | E11: : | F11: 1000
A12: SHIPPEPD QTY. | E12: : | F12: =M34 -> 1013
A13: EXCESS/SHORT QTY. | E13: : | F13: =F12-F11 -> 13
A14: CTN QTY. | E14: : | F14: =N30 -> 16
A15: FABRICATION | E15: : | F15: 100% Cotton, 180 GSM.
A17: CTN NO. | D17: COLOR | G17: SIZE | M17: PCS/CTN | N17: TOTAL CTN | O17: TOTAL QTY | P17: CTN MEAS. | S17: WEIGHT (KGS) | U17: WEIGHT (KGS)
G18: 2 | H18: 4 | I18: 6 | J18: 8 | K18: 10 | L18: 12 | P18: L | Q18: W | R18: H | S18: N.W. | T18: G.W | U18: TTL N.W | V18: TTL G.W
A19: 1 | B19: - | C19: =N19 -> 2 | D19: Surf Blue | G19: 80 | M19: =SUM(G19:L19) -> 80 | N19: 2 | O19: =M19*N19 -> 160 | P19: 51 | Q19: 28 | R19: 22 | S19: 5.5 | T19: =S19+0.9 -> 6.4 | U19: =S19*N19 -> 11 | V19: =T19*N19 -> 12.8
A20: =C19+1 -> 3 | B20: - | C20: =C19+N20 -> 4 | H20: 80 | M20: =SUM(G20:L20) -> 80 | N20: 2 | O20: =M20*N20 -> 160 | S20: 6.1 | T20: =S20+0.9 -> 7 | U20: =S20*N20 -> 12.2 | V20: =T20*N20 -> 14
A21: =C20+1 -> 5 | B21: - | C21: =C20+N21 -> 6 | I21: 70 | M21: =SUM(G21:L21) -> 70 | N21: 2 | O21: =M21*N21 -> 140 | S21: 6.3 | T21: =S21+0.9 -> 7.2 | U21: =S21*N21 -> 12.6 | V21: =T21*N21 -> 14.4
A22: =C21+1 -> 7 | B22: - | C22: =C21+N22 -> 9 | J22: 60 | M22: =SUM(G22:L22) -> 60 | N22: 3 | O22: =M22*N22 -> 180 | S22: 6.1 | T22: =S22+0.9 -> 7 | U22: =S22*N22 -> 18.3 | V22: =T22*N22 -> 21
A23: =C22+1 -> 10 | B23: - | C23: =C22+N23 -> 11 | K23: 55 | M23: =SUM(G23:L23) -> 55 | N23: 2 | O23: =M23*N23 -> 110 | S23: 6.4 | T23: =S23+0.9 -> 7.3 | U23: =S23*N23 -> 12.8 | V23: =T23*N23 -> 14.6
A24: =C23+1 -> 12 | B24: - | C24: =C23+N24 -> 13 | L24: 50 | M24: =SUM(G24:L24) -> 50 | N24: 2 | O24: =M24*N24 -> 100 | S24: 6.6 | T24: =S24+0.9 -> 7.5 | U24: =S24*N24 -> 13.2 | V24: =T24*N24 -> 15
A25: =C24+1 -> 14 | B25: - | C25: =C24+N25 -> 14 | H25: 56 | M25: =SUM(G25:L25) -> 56 | N25: 1 | O25: =M25*N25 -> 56 | S25: 5.1 | T25: =S25+0.9 -> 6 | U25: =S25*N25 -> 5.1 | V25: =T25*N25 -> 6
A26: =C25+1 -> 15 | B26: - | C26: =C25+N26 -> 15 | I26: 67 | M26: =SUM(G26:L26) -> 67 | N26: 1 | O26: =M26*N26 -> 67 | S26: 6 | T26: =S26+0.9 -> 6.9 | U26: =S26*N26 -> 6 | V26: =T26*N26 -> 6.9
A27: =C26+1 -> 16 | B27: - | C27: =C26+N27 -> 16 | G27: 29 | J27: 3 | K27: 6 | L27: 2 | M27: =SUM(G27:L27) -> 40 | N27: 1 | O27: =M27*N27 -> 40 | S27: 3 | T27: =S27+0.9 -> 3.9 | U27: =S27*N27 -> 3 | V27: =T27*N27 -> 3.9
A28: TOTAL | G28: =O19+G27 -> 189 | H28: =O20+H25 -> 216 | I28: =O21+I26 -> 207 | J28: =O22+J27 -> 183 | K28: =O23+K27 -> 116 | L28: =O24+L27 -> 102 | N28: =SUM(N19:N27) -> 16 | O28: =SUM(O19:O27) -> 1013 | P28: =(P19*Q19*R19)/1000000*N28 -> 0.502656 | U28: =SUM(U19:U27) -> 94.2 | V28: =SUM(V19:V27) -> 108.6
A30: GRAND TOTAL | N30: =N28 -> 16 | O30: =O28 -> 1013 | P30: =P28 -> 0.502656 | U30: =U28 -> 94.2 | V30: =V28 -> 108.6
A32: ORDER & SHIP QTY | D32: =D17 -> COLOR | G32: =G18 -> 2 | H32: =H18 -> 4 | I32: =I18 -> 6 | J32: =J18 -> 8 | K32: =K18 -> 10 | L32: =L18 -> 12 | M32: TOTAL
A33: ORDER QTY. | D33: =D19 -> Surf Blue | G33: 200 | H33: 210 | I33: 200 | J33: 180 | K33: 110 | L33: 100 | M33: =G33+H33+I33+J33+K33+L33 -> 1000
A34: SHIP QTY. | G34: =G28 -> 189 | H34: =H28 -> 216 | I34: =I28 -> 207 | J34: =J28 -> 183 | K34: =K28 -> 116 | L34: =L28 -> 102 | M34: =G34+H34+I34+J34+K34+L34 -> 1013

Sheet 683WK
A1: FOUR DESIGN (PVT.) LTD
A2: A 100% Export Oriented Knit Garments
A3: Plot # S - 7 & S - 8, BSCIC, I/E, Fatullah, Narayanganj.
A5: PACKING LIST
A7: BUYER | E7: : | F7: PACIFIC COLLECTIONS | U7: Date:
A8: ORDER NO | E8: : | F8: 53920
A9: ITEM CODE | E9: : | F9: 683WK
A10: ITEM NAME | E10: : | F10: Combi
A11: ORDER QTY. | E11: : | F11: 1370
A12: SHIPPEPD QTY. | E12: : | F12: =M32 -> 1415
A13: EXCESS/SHORT QTY. | E13: : | F13: =F12-F11 -> 45
A14: CTN QTY. | E14: : | F14: =N28 -> 20
A15: FABRICATION | E15: : | F15: 60% Cotton, 40% polyester, 180 GSM.
A17: CTN NO. | D17: COLOR | G17: SIZE | M17: PCS/CTN | N17: TOTAL CTN | O17: TOTAL QTY | P17: CTN MEAS. | S17: WEIGHT (KGS) | U17: WEIGHT (KGS)
G18: 2 | H18: 4 | I18: 6 | J18: 8 | K18: 10 | L18: 12 | P18: L | Q18: W | R18: H | S18: N.W. | T18: G.W | U18: TTL N.W | V18: TTL G.W
A19: 1 | B19: - | C19: =N19 -> 2 | D19: Blue Marl | G19: 75 | M19: =SUM(G19:L19) -> 75 | N19: 2 | O19: =M19*N19 -> 150 | P19: 51 | Q19: 28 | R19: 22 | S19: 5.6 | T19: =S19+0.9 -> 6.5 | U19: =S19*N19 -> 11.2 | V19: =T19*N19 -> 13
A20: =C19+1 -> 3 | B20: - | C20: =C19+N20 -> 7 | H20: 80 | M20: =SUM(G20:L20) -> 80 | N20: 5 | O20: =M20*N20 -> 400 | S20: 6.7 | T20: =S20+0.9 -> 7.6 | U20: =S20*N20 -> 33.5 | V20: =T20*N20 -> 38
A21: =C20+1 -> 8 | B21: - | C21: =C20+N21 -> 11 | I21: 75 | M21: =SUM(G21:L21) -> 75 | N21: 4 | O21: =M21*N21 -> 300 | S21: 7.2 | T21: =S21+0.9 -> 8.1 | U21: =S21*N21 -> 28.8 | V21: =T21*N21 -> 32.4
A22: =C21+1 -> 12 | B22: - | C22: =C21+N22 -> 14 | J22: 70 | M22: =SUM(G22:L22) -> 70 | N22: 3 | O22: =M22*N22 -> 210 | S22: 7.7 | T22: =S22+0.9 -> 8.6 | U22: =S22*N22 -> 23.1 | V22: =T22*N22 -> 25.8
A23: =C22+1 -> 15 | B23: - | C23: =C22+N23 -> 18 | K23: 60 | M23: =SUM(G23:L23) -> 60 | N23: 4 | O23: =M23*N23 -> 240 | S23: 7.6 | T23: =S23+0.9 -> 8.5 | U23: =S23*N23 -> 30.4 | V23: =T23*N23 -> 34
A24: =C23+1 -> 19 | B24: - | C24: =C23+N24 -> 19 | J24: 49 | L24: 24 | M24: =SUM(G24:L24) -> 73 | N24: 1 | O24: =M24*N24 -> 73 | S24: 8.9 | T24: =S24+0.9 -> 9.8 | U24: =S24*N24 -> 8.9 | V24: =T24*N24 -> 9.8
A25: =C24+1 -> 20 | B25: - | C25: =C24+N25 -> 20 | H25: 12 | I25: 10 | K25: 20 | M25: =SUM(G25:L25) -> 42 | N25: 1 | O25: =M25*N25 -> 42 | S25: 4.6 | T25: =S25+0.9 -> 5.5 | U25: =S25*N25 -> 4.6 | V25: =T25*N25 -> 5.5
A26: TOTAL | G26: =O19+G25 -> 150 | H26: =O20+H25 -> 412 | I26: =O21+I25 -> 310 | J26: =O22+J24 -> 259 | K26: =O23+K25 -> 260 | L26: =L24 -> 24 | N26: =SUM(N19:N25) -> 20 | O26: =SUM(O19:O25) -> 1415 | P26: =(P19*Q19*R19)/1000000*N26 -> 0.62832 | U26: =SUM(U19:U25) -> 140.5 | V26: =SUM(V19:V25) -> 158.5
A28: GRAND TOTAL | N28: =N26 -> 20 | O28: =O26 -> 1415 | P28: =P26 -> 0.62832 | U28: =U26 -> 140.5 | V28: =V26 -> 158.5
A30: ORDER & SHIP QTY | D30: =D17 -> COLOR | G30: =G18 -> 2 | H30: =H18 -> 4 | I30: =I18 -> 6 | J30: =J18 -> 8 | K30: =K18 -> 10 | L30: =L18 -> 12 | M30: TOTAL
A31: ORDER QTY. | D31: =D19 -> Blue Marl | G31: 150 | H31: 400 | I31: 300 | J31: 250 | K31: 250 | L31: 20 | M31: =G31+H31+I31+J31+K31+L31 -> 1370
A32: SHIP QTY. | G32: =G26 -> 150 | H32: =H26 -> 412 | I32: =I26 -> 310 | J32: =J26 -> 259 | K32: =K26 -> 260 | L32: =L26 -> 24 | M32: =G32+H32+I32+J32+K32+L32 -> 1415

Sheet 685WK
A1: FOUR DESIGN (PVT.) LTD
A2: A 100% Export Oriented Knit Garments
A3: Plot # S - 7 & S - 8, BSCIC, I/E, Fatullah, Narayanganj.
A5: PACKING LIST
A7: BUYER | E7: : | F7: PACIFIC COLLECTIONS | U7: Date:
A8: ORDER NO | E8: : | F8: 53920
A9: ITEM CODE | E9: : | F9: 685WK
A10: ITEM NAME | E10: : | F10: Two Kiwi
A11: ORDER QTY. | E11: : | F11: 1500
A12: SHIPPEPD QTY. | E12: : | F12: =M34 -> 1539
A13: EXCESS/SHORT QTY. | E13: : | F13: =F12-F11 -> 39
A14: CTN QTY. | E14: : | F14: =N30 -> 22
A15: FABRICATION | E15: : | F15: 100% Cotton, 180 GSM.
A17: CTN NO. | D17: COLOR | G17: SIZE | M17: PCS/CTN | N17: TOTAL CTN | O17: TOTAL QTY | P17: CTN MEAS. | S17: WEIGHT (KGS) | U17: WEIGHT (KGS)
G18: 2 | H18: 4 | I18: 6 | J18: 8 | K18: 10 | L18: 12 | P18: L | Q18: W | R18: H | S18: N.W. | T18: G.W | U18: TTL N.W | V18: TTL G.W
A19: 1 | B19: - | C19: =N19 -> 3 | D19: Coral | G19: 80 | M19: =SUM(G19:L19) -> 80 | N19: 3 | O19: =M19*N19 -> 240 | P19: 51 | Q19: 28 | R19: 22 | S19: 5.1 | T19: =S19+0.9 -> 6 | U19: =S19*N19 -> 15.3 | V19: =T19*N19 -> 18
A20: =C19+1 -> 4 | B20: - | C20: =C19+N20 -> 6 | H20: 80 | M20: =SUM(G20:L20) -> 80 | N20: 3 | O20: =M20*N20 -> 240 | S20: 5.7 | T20: =S20+0.9 -> 6.6 | U20: =S20*N20 -> 17.1 | V20: =T20*N20 -> 19.8
A21: =C20+1 -> 7 | B21: - | C21: =C20+N21 -> 10 | I21: 75 | M21: =SUM(G21:L21) -> 75 | N21: 4 | O21: =M21*N21 -> 300 | S21: 5.8 | T21: =S21+0.9 -> 6.7 | U21: =S21*N21 -> 23.2 | V21: =T21*N21 -> 26.8
A22: =C21+1 -> 11 | B22: - | C22: =C21+N22 -> 13 | J22: 70 | M22: =SUM(G22:L22) -> 70 | N22: 3 | O22: =M22*N22 -> 210 | S22: 6.6 | T22: =S22+0.9 -> 7.5 | U22: =S22*N22 -> 19.8 | V22: =T22*N22 -> 22.5
A23: =C22+1 -> 14 | B23: - | C23: =C22+N23 -> 16 | K23: 65 | M23: =SUM(G23:L23) -> 65 | N23: 3 | O23: =M23*N23 -> 195 | S23: 6.4 | T23: =S23+0.9 -> 7.3 | U23: =S23*N23 -> 19.2 | V23: =T23*N23 -> 21.9
A24: =C23+1 -> 17 | B24: - | C24: =C23+N24 -> 19 | L24: 60 | M24: =SUM(G24:L24) -> 60 | N24: 3 | O24: =M24*N24 -> 180 | S24: 6.3 | T24: =S24+0.9 -> 7.2 | U24: =S24*N24 -> 18.9 | V24: =T24*N24 -> 21.6
A25: =C24+1 -> 20 | B25: - | C25: =C24+N25 -> 20 | H25: 70 | M25: =SUM(G25:L25) -> 70 | N25: 1 | O25: =M25*N25 -> 70 | S25: 6.5 | T25: =S25+0.9 -> 7.4 | U25: =S25*N25 -> 6.5 | V25: =T25*N25 -> 7.4
A26: =C25+1 -> 21 | B26: - | C26: =C25+N26 -> 21 | G26: 13 | L26: 29 | M26: =SUM(G26:L26) -> 42 | N26: 1 | O26: =M26*N26 -> 42 | S26: 2.8 | T26: =S26+0.9 -> 3.7 | U26: =S26*N26 -> 2.8 | V26: =T26*N26 -> 3.7
A27: =C26+1 -> 22 | B27: - | C27: =C26+N27 -> 22 | J27: 50 | K27: 12 | M27: =SUM(G27:L27) -> 62 | N27: 1 | O27: =M27*N27 -> 62 | S27: 6.1 | T27: =S27+0.9 -> 7 | U27: =S27*N27 -> 6.1 | V27: =T27*N27 -> 7
A28: TOTAL | G28: =O19+G26 -> 253 | H28: =O20+H25 -> 310 | I28: =O21+I26 -> 300 | J28: =O22+J27 -> 260 | K28: =O23+K27 -> 207 | L28: =O24+L26 -> 209 | N28: =SUM(N19:N27) -> 22 | O28: =SUM(O19:O27) -> 1539 | P28: =(P19*Q19*R19)/1000000*N28 -> 0.691152 | U28: =SUM(U19:U27) -> 128.9 | V28: =SUM(V19:V27) -> 148.7
A30: GRAND TOTAL | N30: =N28 -> 22 | O30: =O28 -> 1539 | P30: =P28 -> 0.691152 | U30: =U28 -> 128.9 | V30: =V28 -> 148.7
A32: ORDER & SHIP QTY | D32: =D17 -> COLOR | G32: =G18 -> 2 | H32: =H18 -> 4 | I32: =I18 -> 6 | J32: =J18 -> 8 | K32: =K18 -> 10 | L32: =L18 -> 12 | M32: TOTAL
A33: ORDER QTY. | D33: =D19 -> Coral | G33: 250 | H33: 300 | I33: 300 | J33: 250 | K33: 200 | L33: 200 | M33: =G33+H33+I33+J33+K33+L33 -> 1500
A34: SHIP QTY. | G34: =G28 -> 253 | H34: =H28 -> 310 | I34: =I28 -> 300 | J34: =J28 -> 260 | K34: =K28 -> 207 | L34: =L28 -> 209 | M34: =G34+H34+I34+J34+K34+L34 -> 1539

Sheet 688WK
A1: FOUR DESIGN (PVT.) LTD
A2: A 100% Export Oriented Knit Garments
A3: Plot # S - 7 & S - 8, BSCIC, I/E, Fatullah, Narayanganj.
A5: PACKING LIST
A7: BUYER | E7: : | F7: PACIFIC COLLECTIONS | U7: Date:
A8: ORDER NO | E8: : | F8: 53920
A9: ITEM CODE | E9: : | F9: 688WK
A10: ITEM NAME | E10: : | F10: Billion Star Hotel
A11: ORDER QTY. | E11: : | F11: 1550
A12: SHIPPEPD QTY. | E12: : | F12: =M32 -> 1569
A13: EXCESS/SHORT QTY. | E13: : | F13: =F12-F11 -> 19
A14: CTN QTY. | E14: : | F14: =N28 -> 22
A15: FABRICATION | E15: : | F15: 100% Cotton, 180 GSM.
A17: CTN NO. | D17: COLOR | G17: SIZE | M17: PCS/CTN | N17: TOTAL CTN | O17: TOTAL QTY | P17: CTN MEAS. | S17: WEIGHT (KGS) | U17: WEIGHT (KGS)
G18: 2 | H18: 4 | I18: 6 | J18: 8 | K18: 10 | L18: 12 | P18: L | Q18: W | R18: H | S18: N.W. | T18: G.W | U18: TTL N.W | V18: TTL G.W
A19: 1 | B19: - | C19: =N19 -> 4 | D19: Black | G19: 80 | M19: =SUM(G19:L19) -> 80 | N19: 4 | O19: =M19*N19 -> 320 | P19: 51 | Q19: 28 | R19: 22 | S19: 5.1 | T19: =S19+0.9 -> 6 | U19: =S19*N19 -> 20.4 | V19: =T19*N19 -> 24
A20: =C19+1 -> 5 | B20: - | C20: =C19+N20 -> 8 | H20: 80 | M20: =SUM(G20:L20) -> 80 | N20: 4 | O20: =M20*N20 -> 320 | S20: 5.7 | T20: =S20+0.9 -> 6.6 | U20: =S20*N20 -> 22.8 | V20: =T20*N20 -> 26.4
A21: =C20+1 -> 9 | B21: - | C21: =C20+N21 -> 13 | I21: 70 | M21: =SUM(G21:L21) -> 70 | N21: 5 | O21: =M21*N21 -> 350 | S21: 5.8 | T21: =S21+0.9 -> 6.7 | U21: =S21*N21 -> 29 | V21: =T21*N21 -> 33.5
A22: =C21+1 -> 14 | B22: - | C22: =C21+N22 -> 16 | J22: 70 | M22: =SUM(G22:L22) -> 70 | N22: 3 | O22: =M22*N22 -> 210 | S22: 6.6 | T22: =S22+0.9 -> 7.5 | U22: =S22*N22 -> 19.8 | V22: =T22*N22 -> 22.5
A23: =C22+1 -> 17 | B23: - | C23: =C22+N23 -> 20 | K23: 60 | M23: =SUM(G23:L23) -> 60 | N23: 4 | O23: =M23*N23 -> 240 | S23: 6.4 | T23: =S23+0.9 -> 7.3 | U23: =S23*N23 -> 25.6 | V23: =T23*N23 -> 29.2
A24: =C23+1 -> 21 | B24: - | C24: =C23+N24 -> 21 | G24: 28 | H24: 35 | I24: 8 | M24: =SUM(G24:L24) -> 71 | N24: 1 | O24: =M24*N24 -> 71 | S24: 5.8 | T24: =S24+0.9 -> 6.7 | U24: =S24*N24 -> 5.8 | V24: =T24*N24 -> 6.7
A25: =C24+1 -> 22 | B25: - | C25: =C24+N25 -> 22 | J25: 49 | K25: 9 | M25: =SUM(G25:L25) -> 58 | N25: 1 | O25: =M25*N25 -> 58 | S25: 4.6 | T25: =S25+0.9 -> 5.5 | U25: =S25*N25 -> 4.6 | V25: =T25*N25 -> 5.5
A26: TOTAL | G26: =O19+G24 -> 348 | H26: =O20+H24 -> 355 | I26: =O21+I24 -> 358 | J26: =O22+J25 -> 259 | K26: =O23+K25 -> 249 | N26: =SUM(N19:N25) -> 22 | O26: =SUM(O19:O25) -> 1569 | P26: =(P19*Q19*R19)/1000000*N26 -> 0.691152 | U26: =SUM(U19:U25) -> 128 | V26: =SUM(V19:V25) -> 147.8
A28: GRAND TOTAL | N28: =N26 -> 22 | O28: =O26 -> 1569 | P28: =P26 -> 0.691152 | U28: =U26 -> 128 | V28: =V26 -> 147.8
A30: ORDER & SHIP QTY | D30: =D17 -> COLOR | G30: =G18 -> 2 | H30: =H18 -> 4 | I30: =I18 -> 6 | J30: =J18 -> 8 | K30: =K18 -> 10 | L30: =L18 -> 12 | M30: TOTAL
A31: ORDER QTY. | D31: =D19 -> Black | G31: 350 | H31: 350 | I31: 350 | J31: 250 | K31: 250 | M31: =G31+H31+I31+J31+K31+L31 -> 1550
A32: SHIP QTY. | G32: =G26 -> 348 | H32: =H26 -> 355 | I32: =I26 -> 358 | J32: =J26 -> 259 | K32: =K26 -> 249 | L32: =L26 -> 0 | M32: =G32+H32+I32+J32+K32+L32 -> 1569

Sheet 220DF
A1: FOUR DESIGN (PVT.) LTD
A2: A 100% Export Oriented Knit Garments
A3: Plot # S - 7 & S - 8, BSCIC, I/E, Fatullah, Narayanganj.
A5: PACKING LIST
A7: BUYER | E7: : | F7: PACIFIC COLLECTIONS | U7: Date:
A8: ORDER NO | E8: : | F8: 53920
A9: ITEM CODE | E9: : | F9: 220DF
A10: ITEM NAME | E10: : | F10: Dry Fit Polo Shirt
A11: ORDER QTY. | E11: : | F11: 1200
A12: SHIPPEPD QTY. | E12: : | F12: =M33 -> 1243
A13: EXCESS/SHORT QTY. | E13: : | F13: =F12-F11 -> 43
A14: CTN QTY. | E14: : | F14: =N29 -> 33
A15: FABRICATION | E15: : | F15: 100% Polyester, 180 GSM.
A17: CTN NO. | D17: COLOR | G17: SIZE | M17: PCS/CTN | N17: TOTAL CTN | O17: TOTAL QTY | P17: CTN MEAS. | S17: WEIGHT (KGS) | U17: WEIGHT (KGS)
G18: S | H18: M | I18: L | J18: XL | K18: XXL | L18: 3XL | P18: L | Q18: W | R18: H | S18: N.W. | T18: G.W | U18: TTL N.W | V18: TTL G.W
A19: 1 | B19: - | C19: =N19 -> 3 | D19: Black/Grey | G19: 45 | M19: =SUM(G19:L19) -> 45 | N19: 3 | O19: =M19*N19 -> 135 | P19: 55 | Q19: 35 | R19: 26 | S19: 9.7 | T19: =S19+1.2 -> 10.9 | U19: =S19*N19 -> 29.1 | V19: =T19*N19 -> 32.7
A20: =C19+1 -> 4 | B20: - | C20: =C19+N20 -> 9 | H20: 40 | M20: =SUM(G20:L20) -> 40 | N20: 6 | O20: =M20*N20 -> 240 | S20: 9.2 | T20: =S20+1.2 -> 10.4 | U20: =S20*N20 -> 55.2 | V20: =T20*N20 -> 62.4
A21: =C20+1 -> 10 | B21: - | C21: =C20+N21 -> 16 | I21: 40 | M21: =SUM(G21:L21) -> 40 | N21: 7 | O21: =M21*N21 -> 280 | S21: 9.5 | T21: =S21+1.2 -> 10.7 | U21: =S21*N21 -> 66.5 | V21: =T21*N21 -> 74.9
A22: =C21+1 -> 17 | B22: - | C22: =C21+N22 -> 25 | J22: 35 | M22: =SUM(G22:L22) -> 35 | N22: 9 | O22: =M22*N22 -> 315 | S22: 8.5 | T22: =S22+1.2 -> 9.7 | U22: =S22*N22 -> 76.5 | V22: =T22*N22 -> 87.3
A23: =C22+1 -> 26 | B23: - | C23: =C22+N23 -> 30 | K23: 35 | M23: =SUM(G23:L23) -> 35 | N23: 5 | O23: =M23*N23 -> 175 | S23: 9.6 | T23: =S23+1.2 -> 10.8 | U23: =S23*N23 -> 48 | V23: =T23*N23 -> 54
A24: =C23+1 -> 31 | B24: - | C24: =C23+N24 -> 31 | J24: 25 | M24: =SUM(G24:L24) -> 25 | N24: 1 | O24: =M24*N24 -> 25 | S24: 5.2 | T24: =S24+1.2 -> 6.4 | U24: =S24*N24 -> 5.2 | V24: =T24*N24 -> 6.4
A25: =C24+1 -> 32 | B25: - | C25: =C24+N25 -> 32 | G25: 18 | K25: 13 | M25: =SUM(G25:L25) -> 31 | N25: 1 | O25: =M25*N25 -> 31 | S25: 7.8 | T25: =S25+1.2 -> 9 | U25: =S25*N25 -> 7.8 | V25: =T25*N25 -> 9
A26: =C25+1 -> 33 | B26: - | C26: =C25+N26 -> 33 | H26: 13 | I26: 29 | M26: =SUM(G26:L26) -> 42 | N26: 1 | O26: =M26*N26 -> 42 | S26: 9.8 | T26: =S26+1.2 -> 11 | U26: =S26*N26 -> 9.8 | V26: =T26*N26 -> 11
A27: TOTAL | G27: =O19+G25 -> 153 | H27: =O20+H26 -> 253 | I27: =O21+I26 -> 309 | J27: =O22+J24 -> 340 | K27: =O23+K25 -> 188 | N27: =SUM(N19:N26) -> 33 | O27: =SUM(O19:O26) -> 1243 | P27: =(P19*Q19*R19)/1000000*N27 -> 1.65165 | U27: =SUM(U19:U26) -> 298.1 | V27: =SUM(V19:V26) -> 337.7
A29: GRAND TOTAL | N29: =N27 -> 33 | O29: =O27 -> 1243 | P29: =P27 -> 1.65165 | U29: =U27 -> 298.1 | V29: =V27 -> 337.7
A31: ORDER & SHIP QTY | D31: =D17 -> COLOR | G31: =G18 -> S | H31: =H18 -> M | I31: =I18 -> L | J31: =J18 -> XL | K31: =K18 -> XXL | L31: =L18 -> 3XL | M31: TOTAL
A32: ORDER QTY. | D32: =D19 -> Black/Grey | G32: 150 | H32: 240 | I32: 300 | J32: 330 | K32: 180 | M32: =G32+H32+I32+J32+K32+L32 -> 1200
A33: SHIP QTY. | G33: =G27 -> 153 | H33: =H27 -> 253 | I33: =I27 -> 309 | J33: =J27 -> 340 | K33: =K27 -> 188 | L33: =L27 -> 0 | M33: =G33+H33+I33+J33+K33+L33 -> 1243

Sheet 221DF
A1: FOUR DESIGN (PVT.) LTD
A2: A 100% Export Oriented Knit Garments
A3: Plot # S - 7 & S - 8, BSCIC, I/E, Fatullah, Narayanganj.
A5: PACKING LIST
A7: BUYER | E7: : | F7: PACIFIC COLLECTIONS | U7: Date:
A8: ORDER NO | E8: : | F8: 53920
A9: ITEM CODE | E9: : | F9: 221DF
A10: ITEM NAME | E10: : | F10: Ta Moko Dry Fit Polo
A11: ORDER QTY. | E11: : | F11: 1560
A12: SHIPPEPD QTY. | E12: : | F12: =M33 -> 1427
A13: EXCESS/SHORT QTY. | E13: : | F13: =F12-F11 -> -133
A14: CTN QTY. | E14: : | F14: =N29 -> 38
A15: FABRICATION | E15: : | F15: 100% Polyester, 180 GSM.
A17: CTN NO. | D17: COLOR | G17: SIZE | M17: PCS/CTN | N17: TOTAL CTN | O17: TOTAL QTY | P17: CTN MEAS. | S17: WEIGHT (KGS) | U17: WEIGHT (KGS)
G18: S | H18: M | I18: L | J18: XL | K18: XXL | L18: 3XL | P18: L | Q18: W | R18: H | S18: N.W. | T18: G.W | U18: TTL N.W | V18: TTL G.W
A19: 1 | B19: - | C19: =N19 -> 4 | D19: Navy | G19: 45 | M19: =SUM(G19:L19) -> 45 | N19: 4 | O19: =M19*N19 -> 180 | P19: 55 | Q19: 35 | R19: 26 | S19: 9.7 | T19: =S19+1.2 -> 10.9 | U19: =S19*N19 -> 38.8 | V19: =T19*N19 -> 43.6
A20: =C19+1 -> 5 | B20: - | C20: =C19+N20 -> 12 | H20: 40 | M20: =SUM(G20:L20) -> 40 | N20: 8 | O20: =M20*N20 -> 320 | S20: 9.2 | T20: =S20+1.2 -> 10.4 | U20: =S20*N20 -> 73.6 | V20: =T20*N20 -> 83.2
A21: =C20+1 -> 13 | B21: - | C21: =C20+N21 -> 20 | I21: 40 | M21: =SUM(G21:L21) -> 40 | N21: 8 | O21: =M21*N21 -> 320 | S21: 9.5 | T21: =S21+1.2 -> 10.7 | U21: =S21*N21 -> 76 | V21: =T21*N21 -> 85.6
A22: =C21+1 -> 21 | B22: - | C22: =C21+N22 -> 29 | J22: 35 | M22: =SUM(G22:L22) -> 35 | N22: 9 | O22: =M22*N22 -> 315 | S22: 8.5 | T22: =S22+1.2 -> 9.7 | U22: =S22*N22 -> 76.5 | V22: =T22*N22 -> 87.3
A23: =C22+1 -> 30 | B23: - | C23: =C22+N23 -> 35 | K23: 35 | M23: =SUM(G23:L23) -> 35 | N23: 6 | O23: =M23*N23 -> 210 | S23: 9.6 | T23: =S23+1.2 -> 10.8 | U23: =S23*N23 -> 57.6 | V23: =T23*N23 -> 64.8
A24: =C23+1 -> 36 | B24: - | C24: =C23+N24 -> 36 | I24: 24 | M24: =SUM(G24:L24) -> 24 | N24: 1 | O24: =M24*N24 -> 24 | S24: 8.1 | T24: =S24+1.2 -> 9.3 | U24: =S24*N24 -> 8.1 | V24: =T24*N24 -> 9.3
A25: =C24+1 -> 37 | B25: - | C25: =C24+N25 -> 37 | K25: 26 | M25: =SUM(G25:L25) -> 26 | N25: 1 | O25: =M25*N25 -> 26 | S25: 7.8 | T25: =S25+1.2 -> 9 | U25: =S25*N25 -> 7.8 | V25: =T25*N25 -> 9
A26: =C25+1 -> 38 | B26: - | C26: =C25+N26 -> 38 | G26: 19 | J26: 13 | M26: =SUM(G26:L26) -> 32 | N26: 1 | O26: =M26*N26 -> 32 | S26: 8.6 | T26: =S26+1.2 -> 9.8 | U26: =S26*N26 -> 8.6 | V26: =T26*N26 -> 9.8
A27: TOTAL | G27: =O19+G26 -> 199 | H27: =O20+H24 -> 320 | I27: =O21+I24 -> 344 | J27: =O22+J26 -> 328 | K27: =O23+K25 -> 236 | N27: =SUM(N19:N26) -> 38 | O27: =SUM(O19:O26) -> 1427 | P27: =(P19*Q19*R19)/1000000*N27 -> 1.9019 | U27: =SUM(U19:U26) -> 347 | V27: =SUM(V19:V26) -> 392.6
A29: GRAND TOTAL | N29: =N27 -> 38 | O29: =O27 -> 1427 | P29: =P27 -> 1.9019 | U29: =U27 -> 347 | V29: =V27 -> 392.6
A31: ORDER & SHIP QTY | D31: =D17 -> COLOR | G31: =G18 -> S | H31: =H18 -> M | I31: =I18 -> L | J31: =J18 -> XL | K31: =K18 -> XXL | L31: =L18 -> 3XL | M31: TOTAL
A32: ORDER QTY. | D32: =D19 -> Navy | G32: 230 | H32: 350 | I32: 350 | J32: 350 | K32: 280 | M32: =G32+H32+I32+J32+K32+L32 -> 1560
A33: SHIP QTY. | G33: =G27 -> 199 | H33: =H27 -> 320 | I33: =I27 -> 344 | J33: =J27 -> 328 | K33: =K27 -> 236 | L33: =L27 -> 0 | M33: =G33+H33+I33+J33+K33+L33 -> 1427

Sheet 271R
A1: FOUR DESIGN (PVT.) LTD
A2: A 100% Export Oriented Knit Garments
A3: Plot # S - 7 & S - 8, BSCIC, I/E, Fatullah, Narayanganj.
A5: PACKING LIST
A7: BUYER | E7: : | F7: PACIFIC COLLECTIONS | U7: Date:
A8: ORDER NO | E8: : | F8: 53920
A9: ITEM CODE | E9: : | F9: 271R
A10: ITEM NAME | E10: : | F10: Rugby Jersey
A11: ORDER QTY. | E11: : | F11: 1350
A12: SHIPPEPD QTY. | E12: : | F12: =M32 -> 1420
A13: EXCESS/SHORT QTY. | E13: : | F13: =F12-F11 -> 70
A14: CTN QTY. | E14: : | F14: =N28 -> 50
A15: FABRICATION | E15: : | F15: 60% Cotton, 40% Polyester, 300 GSM.
A17: CTN NO. | D17: COLOR | G17: SIZE | M17: PCS/CTN | N17: TOTAL CTN | O17: TOTAL QTY | P17: CTN MEAS. | S17: WEIGHT (KGS) | U17: WEIGHT (KGS)
G18: S | H18: M | I18: L | J18: XL | K18: XXL | L18: 3XL | P18: L | Q18: W | R18: H | S18: N.W. | T18: G.W | U18: TTL N.W | V18: TTL G.W
A19: 1 | B19: - | C19: =N19 -> 7 | D19: Black | G19: 35 | M19: =SUM(G19:L19) -> 35 | N19: 7 | O19: =M19*N19 -> 245 | P19: 55 | Q19: 35 | R19: 26 | S19: 11.9 | T19: =S19+1.2 -> 13.1 | U19: =S19*N19 -> 83.3 | V19: =T19*N19 -> 91.7
A20: =C19+1 -> 8 | B20: - | C20: =C19+N20 -> 18 | H20: 30 | M20: =SUM(G20:L20) -> 30 | N20: 11 | O20: =M20*N20 -> 330 | S20: 10.9 | T20: =S20+1.2 -> 12.1 | U20: =S20*N20 -> 119.9 | V20: =T20*N20 -> 133.1
A21: =C20+1 -> 19 | B21: - | C21: =C20+N21 -> 29 | I21: 30 | M21: =SUM(G21:L21) -> 30 | N21: 11 | O21: =M21*N21 -> 330 | S21: 11.5 | T21: =S21+1.2 -> 12.7 | U21: =S21*N21 -> 126.5 | V21: =T21*N21 -> 139.7
A22: =C21+1 -> 30 | B22: - | C22: =C21+N22 -> 40 | J22: 25 | M22: =SUM(G22:L22) -> 25 | N22: 11 | O22: =M22*N22 -> 275 | S22: 10.2 | T22: =S22+1.2 -> 11.4 | U22: =S22*N22 -> 112.2 | V22: =T22*N22 -> 125.4
A23: =C22+1 -> 41 | B23: - | C23: =C22+N23 -> 48 | K23: 25 | M23: =SUM(G23:L23) -> 25 | N23: 8 | O23: =M23*N23 -> 200 | S23: 10.7 | T23: =S23+1.2 -> 11.9 | U23: =S23*N23 -> 85.6 | V23: =T23*N23 -> 95.2
A24: =C23+1 -> 49 | B24: - | C24: =C23+N24 -> 49 | G24: 7 | I24: 14 | M24: =SUM(G24:L24) -> 21 | N24: 1 | O24: =M24*N24 -> 21 | S24: 8.8 | T24: =S24+1.2 -> 10 | U24: =S24*N24 -> 8.8 | V24: =T24*N24 -> 10
A25: =C24+1 -> 50 | B25: - | C25: =C24+N25 -> 50 | H25: 7 | J25: 7 | K25: 5 | M25: =SUM(G25:L25) -> 19 | N25: 1 | O25: =M25*N25 -> 19 | S25: 7.7 | T25: =S25+1.2 -> 8.9 | U25: =S25*N25 -> 7.7 | V25: =T25*N25 -> 8.9
A26: TOTAL | G26: =O19+G24 -> 252 | H26: =O20+H25 -> 337 | I26: =O21+I24 -> 344 | J26: =O22+J25 -> 282 | K26: =O23+K25 -> 205 | N26: =SUM(N19:N25) -> 50 | O26: =SUM(O19:O25) -> 1420 | P26: =(P19*Q19*R19)/1000000*N26 -> 2.5025 | U26: =SUM(U19:U25) -> 544 | V26: =SUM(V19:V25) -> 604
A28: GRAND TOTAL | N28: =N26 -> 50 | O28: =O26 -> 1420 | P28: =P26 -> 2.5025 | U28: =U26 -> 544 | V28: =V26 -> 604
A30: ORDER & SHIP QTY | D30: =D17 -> COLOR | G30: =G18 -> S | H30: =H18 -> M | I30: =I18 -> L | J30: =J18 -> XL | K30: =K18 -> XXL | L30: =L18 -> 3XL | M30: TOTAL
A31: ORDER QTY. | D31: =D19 -> Black | G31: 250 | H31: 300 | I31: 350 | J31: 270 | K31: 180 | M31: =G31+H31+I31+J31+K31+L31 -> 1350
A32: SHIP QTY. | G32: =G26 -> 252 | H32: =H26 -> 337 | I32: =I26 -> 344 | J32: =J26 -> 282 | K32: =K26 -> 205 | M32: =G32+H32+I32+J32+K32+L32 -> 1420

Sheet KMP58
A1: FOUR DESIGN (PVT.) LTD
A2: A 100% Export Oriented Knit Garments
A3: Plot # S - 7 & S - 8, BSCIC, I/E, Fatullah, Narayanganj.
A5: PACKING LIST
A7: BUYER | E7: : | F7: PACIFIC COLLECTIONS | U7: Date:
A8: ORDER NO | E8: : | F8: 53920
A9: ITEM CODE | E9: : | F9: KMP58
A10: ITEM NAME | E10: : | F10: Ngaru Polo Shirt
A11: ORDER QTY. | E11: : | F11: 1650
A12: SHIPPEPD QTY. | E12: : | F12: =M33 -> 1683
A13: EXCESS/SHORT QTY. | E13: : | F13: =F12-F11 -> 33
A14: CTN QTY. | E14: : | F14: =N29 -> 70
A15: FABRICATION | E15: : | F15: 100% Cotton, 250 GSM.
A17: CTN NO. | D17: COLOR | G17: SIZE | M17: PCS/CTN | N17: TOTAL CTN | O17: TOTAL QTY | P17: CTN MEAS. | S17: WEIGHT (KGS) | U17: WEIGHT (KGS)
G18: S | H18: M | I18: L | J18: XL | K18: XXL | L18: 3XL | P18: L | Q18: W | R18: H | S18: N.W. | T18: G.W | U18: TTL N.W | V18: TTL G.W
A19: 1 | B19: - | C19: =N19 -> 3 | D19: Navy | G19: 30 | M19: =SUM(G19:L19) -> 30 | N19: 3 | O19: =M19*N19 -> 90 | P19: 55 | Q19: 32 | R19: 26 | S19: 9.5 | T19: =S19+1.1 -> 10.6 | U19: =S19*N19 -> 28.5 | V19: =T19*N19 -> 31.8
A20: =C19+1 -> 4 | B20: - | C20: =C19+N20 -> 11 | H20: 30 | M20: =SUM(G20:L20) -> 30 | N20: 8 | O20: =M20*N20 -> 240 | S20: 10.1 | T20: =S20+1.1 -> 11.2 | U20: =S20*N20 -> 80.8 | V20: =T20*N20 -> 89.6
A21: =C20+1 -> 12 | B21: - | C21: =C20+N21 -> 27 | I21: 25 | M21: =SUM(G21:L21) -> 25 | N21: 16 | O21: =M21*N21 -> 400 | S21: 9 | T21: =S21+1.1 -> 10.1 | U21: =S21*N21 -> 144 | V21: =T21*N21 -> 161.6
A22: =C21+1 -> 28 | B22: - | C22: =C21+N22 -> 43 | J22: 25 | M22: =SUM(G22:L22) -> 25 | N22: 16 | O22: =M22*N22 -> 400 | S22: 9.4 | T22: =S22+1.1 -> 10.5 | U22: =S22*N22 -> 150.4 | V22: =T22*N22 -> 168
A23: =C22+1 -> 44 | B23: - | C23: =C22+N23 -> 58 | K23: 20 | M23: =SUM(G23:L23) -> 20 | N23: 15 | O23: =M23*N23 -> 300 | S23: 8.1 | T23: =S23+1.1 -> 9.2 | U23: =S23*N23 -> 121.5 | V23: =T23*N23 -> 138
A24: =C23+1 -> 59 | B24: - | C24: =C23+N24 -> 68 | L24: 20 | M24: =SUM(G24:L24) -> 20 | N24: 10 | O24: =M24*N24 -> 200 | S24: 8.6 | T24: =S24+1.1 -> 9.7 | U24: =S24*N24 -> 86 | V24: =T24*N24 -> 97
A25: =C24+1 -> 69 | B25: - | C25: =C24+N25 -> 69 | G25: 14 | H25: 11 | L25: 3 | M25: =SUM(G25:L25) -> 28 | N25: 1 | O25: =M25*N25 -> 28 | S25: 9.5 | T25: =S25+1.1 -> 10.6 | U25: =S25*N25 -> 9.5 | V25: =T25*N25 -> 10.6
A26: =C25+1 -> 70 | B26: - | C26: =C25+N26 -> 70 | I26: 4 | J26: 13 | K26: 8 | M26: =SUM(G26:L26) -> 25 | N26: 1 | O26: =M26*N26 -> 25 | S26: 9 | T26: =S26+1.1 -> 10.1 | U26: =S26*N26 -> 9 | V26: =T26*N26 -> 10.1
A27: TOTAL | G27: =O19+G25 -> 104 | H27: =O20+H25 -> 251 | I27: =O21+I26 -> 404 | J27: =O22+J26 -> 413 | K27: =O23+K26 -> 308 | L27: =O24+L25 -> 203 | N27: =SUM(N19:N26) -> 70 | O27: =SUM(O19:O26) -> 1683 | P27: =(P19*Q19*R19)/1000000*N27 -> 3.2032 | U27: =SUM(U19:U26) -> 629.7 | V27: =SUM(V19:V26) -> 706.7
A29: GRAND TOTAL | N29: =N27 -> 70 | O29: =O27 -> 1683 | P29: =P27 -> 3.2032 | U29: =U27 -> 629.7 | V29: =V27 -> 706.7
A31: ORDER & SHIP QTY | D31: =D17 -> COLOR | G31: =G18 -> S | H31: =H18 -> M | I31: =I18 -> L | J31: =J18 -> XL | K31: =K18 -> XXL | L31: =L18 -> 3XL | M31: TOTAL
A32: ORDER QTY. | D32: =D19 -> Navy | G32: 100 | H32: 250 | I32: 400 | J32: 400 | K32: 300 | L32: 200 | M32: =G32+H32+I32+J32+K32+L32 -> 1650
A33: SHIP QTY. | G33: =G27 -> 104 | H33: =H27 -> 251 | I33: =I27 -> 404 | J33: =J27 -> 413 | K33: =K27 -> 308 | L33: =L27 -> 203 | M33: =G33+H33+I33+J33+K33+L33 -> 1683

Sheet KMT41
A1: FOUR DESIGN (PVT.) LTD
A2: A 100% Export Oriented Knit Garments
A3: Plot # S - 7 & S - 8, BSCIC, I/E, Fatullah, Narayanganj.
A5: PACKING LIST
A7: BUYER | E7: : | F7: PACIFIC COLLECTIONS | U7: Date:
A8: ORDER NO | E8: : | F8: 53920
A9: ITEM CODE | E9: : | F9: KMT41
A10: ITEM NAME | E10: : | F10: Raumati Tee
A11: ORDER QTY. | E11: : | F11: 1430
A12: SHIPPEPD QTY. | E12: : | F12: =M34 -> 1470
A13: EXCESS/SHORT QTY. | E13: : | F13: =F12-F11 -> 40
A14: CTN QTY. | E14: : | F14: =N30 -> 29
A15: FABRICATION | E15: : | F15: 100% Cotton, 180 GSM.
A17: CTN NO. | D17: COLOR | G17: SIZE | M17: PCS/CTN | N17: TOTAL CTN | O17: TOTAL QTY | P17: CTN MEAS. | S17: WEIGHT (KGS) | U17: WEIGHT (KGS)
G18: S | H18: M | I18: L | J18: XL | K18: XXL | L18: 3XL | P18: L | Q18: W | R18: H | S18: N.W. | T18: G.W | U18: TTL N.W | V18: TTL G.W
A19: 1 | B19: - | C19: =N19 -> 3 | D19: Sage | G19: 60 | M19: =SUM(G19:L19) -> 60 | N19: 3 | O19: =M19*N19 -> 180 | P19: 55 | Q19: 35 | R19: 26 | S19: 10.9 | T19: =S19+1.2 -> 12.1 | U19: =S19*N19 -> 32.7 | V19: =T19*N19 -> 36.3
A20: =C19+1 -> 4 | B20: - | C20: =C19+N20 -> 8 | H20: 60 | M20: =SUM(G20:L20) -> 60 | N20: 5 | O20: =M20*N20 -> 300 | S20: 11.8 | T20: =S20+1.2 -> 13 | U20: =S20*N20 -> 59 | V20: =T20*N20 -> 65
A21: =C20+1 -> 9 | B21: - | C21: =C20+N21 -> 14 | I21: 50 | M21: =SUM(G21:L21) -> 50 | N21: 6 | O21: =M21*N21 -> 300 | S21: 9.8 | T21: =S21+1.2 -> 11 | U21: =S21*N21 -> 58.8 | V21: =T21*N21 -> 66
A22: =C21+1 -> 15 | B22: - | C22: =C21+N22 -> 19 | J22: 50 | M22: =SUM(G22:L22) -> 50 | N22: 5 | O22: =M22*N22 -> 250 | S22: 10.8 | T22: =S22+1.2 -> 12 | U22: =S22*N22 -> 54 | V22: =T22*N22 -> 60
A23: =C22+1 -> 20 | B23: - | C23: =C22+N23 -> 23 | K23: 45 | M23: =SUM(G23:L23) -> 45 | N23: 4 | O23: =M23*N23 -> 180 | S23: 10.7 | T23: =S23+1.2 -> 11.9 | U23: =S23*N23 -> 42.8 | V23: =T23*N23 -> 47.6
A24: =C23+1 -> 24 | B24: - | C24: =C23+N24 -> 26 | L24: 45 | M24: =SUM(G24:L24) -> 45 | N24: 3 | O24: =M24*N24 -> 135 | S24: 11.5 | T24: =S24+1.2 -> 12.7 | U24: =S24*N24 -> 34.5 | V24: =T24*N24 -> 38.1
A25: =C24+1 -> 27 | B25: - | C25: =C24+N25 -> 27 | G25: 42 | J25: 14 | M25: =SUM(G25:L25) -> 56 | N25: 1 | O25: =M25*N25 -> 56 | S25: 10.8 | T25: =S25+1.2 -> 12 | U25: =S25*N25 -> 10.8 | V25: =T25*N25 -> 12
A26: =C25+1 -> 28 | B26: - | C26: =C25+N26 -> 28 | H26: 11 | I26: 9 | L26: 19 | M26: =SUM(G26:L26) -> 39 | N26: 1 | O26: =M26*N26 -> 39 | S26: 10.9 | T26: =S26+1.2 -> 12.1 | U26: =S26*N26 -> 10.9 | V26: =T26*N26 -> 12.1
A27: =C26+1 -> 29 | B27: - | C27: =C26+N27 -> 29 | K27: 30 | M27: =SUM(G27:L27) -> 30 | N27: 1 | O27: =M27*N27 -> 30 | S27: 10.8 | T27: =S27+1.2 -> 12 | U27: =S27*N27 -> 10.8 | V27: =T27*N27 -> 12
A28: TOTAL | G28: =O19+G25 -> 222 | H28: =O20+H26 -> 311 | I28: =O21+I26 -> 309 | J28: =O22+J25 -> 264 | K28: =O23+K27 -> 210 | L28: =O24+L26 -> 154 | N28: =SUM(N19:N27) -> 29 | O28: =SUM(O19:O27) -> 1470 | P28: =(P19*Q19*R19)/1000000*N28 -> 1.45145 | U28: =SUM(U19:U27) -> 314.3 | V28: =SUM(V19:V27) -> 349.1
A30: GRAND TOTAL | N30: =N28 -> 29 | O30: =O28 -> 1470 | P30: =P28 -> 1.45145 | U30: =U28 -> 314.3 | V30: =V28 -> 349.1
A32: ORDER & SHIP QTY | D32: =D17 -> COLOR | G32: =G18 -> S | H32: =H18 -> M | I32: =I18 -> L | J32: =J18 -> XL | K32: =K18 -> XXL | L32: =L18 -> 3XL | M32: TOTAL
A33: ORDER QTY. | D33: =D19 -> Sage | G33: 220 | H33: 300 | I33: 300 | J33: 260 | K33: 200 | L33: 150 | M33: =G33+H33+I33+J33+K33+L33 -> 1430
A34: SHIP QTY. | G34: =G28 -> 222 | H34: =H28 -> 311 | I34: =I28 -> 309 | J34: =J28 -> 264 | K34: =K28 -> 210 | L34: =L28 -> 154 | M34: =G34+H34+I34+J34+K34+L34 -> 1470

Sheet KMT42
A1: FOUR DESIGN (PVT.) LTD
A2: A 100% Export Oriented Knit Garments
A3: Plot # S - 7 & S - 8, BSCIC, I/E, Fatullah, Narayanganj.
A5: PACKING LIST
A7: BUYER | E7: : | F7: PACIFIC COLLECTIONS | U7: Date:
A8: ORDER NO | E8: : | F8: 53920
A9: ITEM CODE | E9: : | F9: KMT42
A10: ITEM NAME | E10: : | F10: Ngaru
A11: ORDER QTY. | E11: : | F11: 1300
A12: SHIPPEPD QTY. | E12: : | F12: =M33 -> 1337
A13: EXCESS/SHORT QTY. | E13: : | F13: =F12-F11 -> 37
A14: CTN QTY. | E14: : | F14: =N29 -> 28
A15: FABRICATION | E15: : | F15: 100% Cotton, 180 GSM.
A17: CTN NO. | D17: COLOR | G17: SIZE | M17: PCS/CTN | N17: TOTAL CTN | O17: TOTAL QTY | P17: CTN MEAS. | S17: WEIGHT (KGS) | U17: WEIGHT (KGS)
G18: S | H18: M | I18: L | J18: XL | K18: XXL | L18: 3XL | P18: L | Q18: W | R18: H | S18: N.W. | T18: G.W | U18: TTL N.W | V18: TTL G.W
A19: 1 | B19: - | C19: =N19 -> 3 | D19: Teal | G19: 60 | M19: =SUM(G19:L19) -> 60 | N19: 3 | O19: =M19*N19 -> 180 | P19: 55 | Q19: 35 | R19: 26 | S19: 8.5 | T19: =S19+1.2 -> 9.7 | U19: =S19*N19 -> 25.5 | V19: =T19*N19 -> 29.1
A20: =C19+1 -> 4 | B20: - | C20: =C19+N20 -> 7 | H20: 60 | M20: =SUM(G20:L20) -> 60 | N20: 4 | O20: =M20*N20 -> 240 | S20: 9.2 | T20: =S20+1.2 -> 10.4 | U20: =S20*N20 -> 36.8 | V20: =T20*N20 -> 41.6
A21: =C20+1 -> 8 | B21: - | C21: =C20+N21 -> 12 | I21: 50 | M21: =SUM(G21:L21) -> 50 | N21: 5 | O21: =M21*N21 -> 250 | S21: 8.3 | T21: =S21+1.2 -> 9.5 | U21: =S21*N21 -> 41.5 | V21: =T21*N21 -> 47.5
A22: =C21+1 -> 13 | B22: - | C22: =C21+N22 -> 16 | J22: 50 | M22: =SUM(G22:L22) -> 50 | N22: 4 | O22: =M22*N22 -> 200 | S22: 8.8 | T22: =S22+1.2 -> 10 | U22: =S22*N22 -> 35.2 | V22: =T22*N22 -> 40
A23: =C22+1 -> 17 | B23: - | C23: =C22+N23 -> 21 | K23: 40 | M23: =SUM(G23:L23) -> 40 | N23: 5 | O23: =M23*N23 -> 200 | S23: 9.6 | T23: =S23+1.2 -> 10.8 | U23: =S23*N23 -> 48 | V23: =T23*N23 -> 54
A24: =C23+1 -> 22 | B24: - | C24: =C23+N24 -> 26 | L24: 40 | M24: =SUM(G24:L24) -> 40 | N24: 5 | O24: =M24*N24 -> 200 | S24: 9.7 | T24: =S24+1.2 -> 10.9 | U24: =S24*N24 -> 48.5 | V24: =T24*N24 -> 54.5
A25: =C24+1 -> 27 | B25: - | C25: =C24+N25 -> 27 | G25: 27 | I25: 9 | M25: =SUM(G25:L25) -> 36 | N25: 1 | O25: =M25*N25 -> 36 | S25: 3.6 | T25: =S25+1.2 -> 4.8 | U25: =S25*N25 -> 3.6 | V25: =T25*N25 -> 4.8
A26: =C25+1 -> 28 | B26: - | C26: =C25+N26 -> 28 | H26: 22 | J26: 2 | L26: 7 | M26: =SUM(G26:L26) -> 31 | N26: 1 | O26: =M26*N26 -> 31 | S26: 3.6 | T26: =S26+1.2 -> 4.8 | U26: =S26*N26 -> 3.6 | V26: =T26*N26 -> 4.8
A27: TOTAL | G27: =O19+G25 -> 207 | H27: =O20+H26 -> 262 | I27: =O21+I25 -> 259 | J27: =O22+J26 -> 202 | K27: =O23 -> 200 | L27: =O24+L26 -> 207 | N27: =SUM(N19:N26) -> 28 | O27: =SUM(O19:O26) -> 1337 | P27: =(P19*Q19*R19)/1000000*N27 -> 1.4014 | U27: =SUM(U19:U26) -> 242.7 | V27: =SUM(V19:V26) -> 276.3
A29: GRAND TOTAL | N29: =N27 -> 28 | O29: =O27 -> 1337 | P29: =P27 -> 1.4014 | U29: =U27 -> 242.7 | V29: =V27 -> 276.3
A31: ORDER & SHIP QTY | D31: =D17 -> COLOR | G31: =G18 -> S | H31: =H18 -> M | I31: =I18 -> L | J31: =J18 -> XL | K31: =K18 -> XXL | L31: =L18 -> 3XL | M31: TOTAL
A32: ORDER QTY. | D32: =D19 -> Teal | G32: 200 | H32: 250 | I32: 250 | J32: 200 | K32: 200 | L32: 200 | M32: =G32+H32+I32+J32+K32+L32 -> 1300
A33: SHIP QTY. | G33: =G27 -> 207 | H33: =H27 -> 262 | I33: =I27 -> 259 | J33: =J27 -> 202 | K33: =K27 -> 200 | L33: =L27 -> 207 | M33: =G33+H33+I33+J33+K33+L33 -> 1337

Sheet KWH88
A1: FOUR DESIGN (PVT.) LTD
A2: A 100% Export Oriented Knit Garments
A3: Plot # S - 7 & S - 8, BSCIC, I/E, Fatullah, Narayanganj.
A5: PACKING LIST
A7: BUYER | E7: : | F7: PACIFIC COLLECTIONS | U7: Date:
A8: ORDER NO | E8: : | F8: 53920
A9: ITEM CODE | E9: : | F9: KWH88
A10: ITEM NAME | E10: : | F10: Womens Kaha Hoodie
A11: ORDER QTY. | E11: : | F11: 1100
A12: SHIPPEPD QTY. | E12: : | F12: =M33 -> 1104
A13: EXCESS/SHORT QTY. | E13: : | F13: =F12-F11 -> 4
A14: CTN QTY. | E14: : | F14: =N29 -> 52
A15: FABRICATION | E15: : | F15: 100% Cotton, 350 GSM.
A17: CTN NO. | D17: COLOR | G17: SIZE | M17: PCS/CTN | N17: TOTAL CTN | O17: TOTAL QTY | P17: CTN MEAS. | S17: WEIGHT (KGS) | U17: WEIGHT (KGS)
G18: S | H18: M | I18: L | J18: XL | K18: XXL | L18: 3XL | P18: L | Q18: W | R18: H | S18: N.W. | T18: G.W | U18: TTL N.W | V18: TTL G.W
A19: 1 | B19: - | C19: =N19 -> 7 | D19: Black | G19: 25 | M19: =SUM(G19:L19) -> 25 | N19: 7 | O19: =M19*N19 -> 175 | P19: 60 | Q19: 41 | R19: 40 | S19: 15.2 | T19: =S19+1.2 -> 16.4 | U19: =S19*N19 -> 106.4 | V19: =T19*N19 -> 114.8
A20: =C19+1 -> 8 | B20: - | C20: =C19+N20 -> 15 | H20: 25 | M20: =SUM(G20:L20) -> 25 | N20: 8 | O20: =M20*N20 -> 200 | S20: 16 | T20: =S20+1.2 -> 17.2 | U20: =S20*N20 -> 128 | V20: =T20*N20 -> 137.6
A21: =C20+1 -> 16 | B21: - | C21: =C20+N21 -> 25 | I21: 20 | M21: =SUM(G21:L21) -> 20 | N21: 10 | O21: =M21*N21 -> 200 | S21: 13.6 | T21: =S21+1.2 -> 14.8 | U21: =S21*N21 -> 136 | V21: =T21*N21 -> 148
A22: =C21+1 -> 26 | B22: - | C22: =C21+N22 -> 35 | J22: 20 | M22: =SUM(G22:L22) -> 20 | N22: 10 | O22: =M22*N22 -> 200 | S22: 14.2 | T22: =S22+1.2 -> 15.4 | U22: =S22*N22 -> 142 | V22: =T22*N22 -> 154
A23: =C22+1 -> 36 | B23: - | C23: =C22+N23 -> 45 | K23: 20 | M23: =SUM(G23:L23) -> 20 | N23: 10 | O23: =M23*N23 -> 200 | S23: 14.9 | T23: =S23+1.2 -> 16.1 | U23: =S23*N23 -> 149 | V23: =T23*N23 -> 161
A24: =C23+1 -> 46 | B24: - | C24: =C23+N24 -> 50 | L24: 20 | M24: =SUM(G24:L24) -> 20 | N24: 5 | O24: =M24*N24 -> 100 | S24: 15.7 | T24: =S24+1.2 -> 16.9 | U24: =S24*N24 -> 78.5 | V24: =T24*N24 -> 84.5
A25: =C24+1 -> 51 | B25: - | C25: =C24+N25 -> 51 | G25: 20 | I25: 1 | L25: 2 | M25: =SUM(G25:L25) -> 23 | N25: 1 | O25: =M25*N25 -> 23 | S25: 14.6 | T25: =S25+1.2 -> 15.8 | U25: =S25*N25 -> 14.6 | V25: =T25*N25 -> 15.8
A26: =C25+1 -> 52 | B26: - | C26: =C25+N26 -> 52 | H26: 11 | J26: 9 | K26: 4 | M26: =SUM(G26:L26) -> 24 | N26: 1 | O26: =M26*N26 -> 24 | S26: 16.4 | T26: =S26+1.2 -> 17.6 | U26: =S26*N26 -> 16.4 | V26: =T26*N26 -> 17.6
A27: TOTAL | G27: =O19+G25 -> 195 | H27: =O20+H25 -> 200 | I27: =O21+I26 -> 200 | J27: =O22+J26 -> 209 | K27: =O23 -> 200 | L27: =O24+L26 -> 100 | N27: =SUM(N19:N26) -> 52 | O27: =SUM(O19:O26) -> 1122 | P27: =(P19*Q19*R19)/1000000*N27 -> 5.1168 | U27: =SUM(U19:U26) -> 770.9 | V27: =SUM(V19:V26) -> 833.3
A29: GRAND TOTAL | N29: =N27 -> 52 | O29: =O27 -> 1122 | P29: =P27 -> 5.1168 | U29: =U27 -> 770.9 | V29: =V27 -> 833.3
A31: ORDER & SHIP QTY | D31: =D17 -> COLOR | G31: =G18 -> S | H31: =H18 -> M | I31: =I18 -> L | J31: =J18 -> XL | K31: =K18 -> XXL | L31: =L18 -> 3XL | M31: TOTAL
A32: ORDER QTY. | D32: =D19 -> Black | G32: 200 | H32: 200 | I32: 200 | J32: 200 | K32: 200 | L32: 100 | M32: =G32+H32+I32+J32+K32+L32 -> 1100
A33: SHIP QTY. | G33: =G27 -> 195 | H33: =H27 -> 200 | I33: =I27 -> 200 | J33: =J27 -> 209 | K33: =K27 -> 200 | L33: =L27 -> 100 | M33: =G33+H33+I33+J33+K33+L33 -> 1104

Sheet KWT70
A1: FOUR DESIGN (PVT.) LTD
A2: A 100% Export Oriented Knit Garments
A3: Plot # S - 7 & S - 8, BSCIC, I/E, Fatullah, Narayanganj.
A5: PACKING LIST
A7: BUYER | E7: : | F7: PACIFIC COLLECTIONS | U7: Date:
A8: ORDER NO | E8: : | F8: 53920
A9: ITEM CODE | E9: : | F9: KWT70
A10: ITEM NAME | E10: : | F10: Ngaru Tee
A11: ORDER QTY. | E11: : | F11: 1000
A12: SHIPPEPD QTY. | E12: : | F12: =M33 -> 1029
A13: EXCESS/SHORT QTY. | E13: : | F13: =F12-F11 -> 29
A14: CTN QTY. | E14: : | F14: =N29 -> 19
A15: FABRICATION | E15: : | F15: 100% Cotton, 180 GSM.
A17: CTN NO. | D17: COLOR | G17: SIZE | M17: PCS/CTN | N17: TOTAL CTN | O17: TOTAL QTY | P17: CTN MEAS. | S17: WEIGHT (KGS) | U17: WEIGHT (KGS)
G18: S | H18: M | I18: L | J18: XL | K18: XXL | L18: 3XL | P18: L | Q18: W | R18: H | S18: N.W. | T18: G.W | U18: TTL N.W | V18: TTL G.W
A19: 1 | B19: - | C19: =N19 -> 3 | D19: Jade | G19: 60 | M19: =SUM(G19:L19) -> 60 | N19: 3 | O19: =M19*N19 -> 180 | P19: 55 | Q19: 28 | R19: 28 | S19: 9.2 | T19: =S19+1 -> 10.2 | U19: =S19*N19 -> 27.6 | V19: =T19*N19 -> 30.6
A20: =C19+1 -> 4 | B20: - | C20: =C19+N20 -> 6 | H20: 60 | M20: =SUM(G20:L20) -> 60 | N20: 3 | O20: =M20*N20 -> 180 | S20: 9.3 | T20: =S20+1 -> 10.3 | U20: =S20*N20 -> 27.9 | V20: =T20*N20 -> 30.9
A21: =C20+1 -> 7 | B21: - | C21: =C20+N21 -> 10 | I21: 50 | M21: =SUM(G21:L21) -> 50 | N21: 4 | O21: =M21*N21 -> 200 | S21: 9.7 | T21: =S21+1 -> 10.7 | U21: =S21*N21 -> 38.8 | V21: =T21*N21 -> 42.8
A22: =C21+1 -> 11 | B22: - | C22: =C21+N22 -> 14 | J22: 50 | M22: =SUM(G22:L22) -> 50 | N22: 4 | O22: =M22*N22 -> 200 | S22: 9.9 | T22: =S22+1 -> 10.9 | U22: =S22*N22 -> 39.6 | V22: =T22*N22 -> 43.6
A23: =C22+1 -> 15 | B23: - | C23: =C22+N23 -> 16 | K23: 45 | M23: =SUM(G23:L23) -> 45 | N23: 2 | O23: =M23*N23 -> 90 | S23: 9.5 | T23: =S23+1 -> 10.5 | U23: =S23*N23 -> 19 | V23: =T23*N23 -> 21
A24: =C23+1 -> 17 | B24: - | C24: =C23+N24 -> 17 | L24: 40 | M24: =SUM(G24:L24) -> 40 | N24: 1 | O24: =M24*N24 -> 40 | S24: 9.2 | T24: =S24+1 -> 10.2 | U24: =S24*N24 -> 9.2 | V24: =T24*N24 -> 10.2
A25: =C24+1 -> 18 | B25: - | C25: =C24+N25 -> 18 | G25: 34 | I25: 18 | K25: 12 | M25: =SUM(G25:L25) -> 64 | N25: 1 | O25: =M25*N25 -> 64 | S25: 9.2 | T25: =S25+1 -> 10.2 | U25: =S25*N25 -> 9.2 | V25: =T25*N25 -> 10.2
A26: =C25+1 -> 19 | B26: - | C26: =C25+N26 -> 19 | H26: 37 | J26: 15 | L26: 23 | M26: =SUM(G26:L26) -> 75 | N26: 1 | O26: =M26*N26 -> 75 | S26: 9.7 | T26: =S26+1 -> 10.7 | U26: =S26*N26 -> 9.7 | V26: =T26*N26 -> 10.7
A27: TOTAL | G27: =O19+G25 -> 214 | H27: =O20+H26 -> 217 | I27: =O21+I25 -> 218 | J27: =O22+J26 -> 215 | K27: =O23+K25 -> 102 | L27: =O24+L26 -> 63 | N27: =SUM(N19:N26) -> 19 | O27: =SUM(O19:O26) -> 1029 | P27: =(P19*Q19*R19)/1000000*N27 -> 0.81928 | U27: =SUM(U19:U26) -> 181 | V27: =SUM(V19:V26) -> 200
A29: GRAND TOTAL | N29: =N27 -> 19 | O29: =O27 -> 1029 | P29: =P27 -> 0.81928 | U29: =U27 -> 181 | V29: =V27 -> 200
A31: ORDER & SHIP QTY | D31: =D17 -> COLOR | G31: =G18 -> S | H31: =H18 -> M | I31: =I18 -> L | J31: =J18 -> XL | K31: =K18 -> XXL | L31: =L18 -> 3XL | M31: TOTAL
A32: ORDER QTY. | D32: =D19 -> Jade | G32: 210 | H32: 210 | I32: 210 | J32: 210 | K32: 100 | L32: 60 | M32: =G32+H32+I32+J32+K32+L32 -> 1000
A33: SHIP QTY. | G33: =G27 -> 214 | H33: =H27 -> 217 | I33: =I27 -> 218 | J33: =J27 -> 215 | K33: =K27 -> 102 | L33: =L27 -> 63 | M33: =G33+H33+I33+J33+K33+L33 -> 1029

Sheet 26QT
A1: FOUR DESIGN (PVT.) LTD
A2: A 100% Export Oriented Knit Garments
A3: Plot # S - 7 & S - 8, BSCIC, I/E, Fatullah, Narayanganj.
A5: PACKING LIST
A7: BUYER | E7: : | F7: PACIFIC COLLECTIONS | U7: Date:
A8: ORDER NO | E8: : | F8: 53920
A9: ITEM CODE | E9: : | F9: 26QT
A10: ITEM NAME | E10: : | F10: Queenstown
A11: ORDER QTY. | E11: : | F11: 2100
A12: SHIPPEPD QTY. | E12: : | F12: =M33 -> 2123
A13: EXCESS/SHORT QTY. | E13: : | F13: =F12-F11 -> 23
A14: CTN QTY. | E14: : | F14: =N29 -> 40
A15: FABRICATION | E15: : | F15: 100% Cotton, 150 GSM.
A17: CTN NO. | D17: COLOR | G17: SIZE | M17: PCS/CTN | N17: TOTAL CTN | O17: TOTAL QTY | P17: CTN MEAS. | S17: WEIGHT (KGS) | U17: WEIGHT (KGS)
G18: S | H18: M | I18: L | J18: XL | K18: XXL | L18: 3XL | P18: L | Q18: W | R18: H | S18: N.W. | T18: G.W | U18: TTL N.W | V18: TTL G.W
A19: 1 | B19: - | C19: =N19 -> 6 | D19: Navy | G19: 60 | M19: =SUM(G19:L19) -> 60 | N19: 6 | O19: =M19*N19 -> 360 | P19: 55 | Q19: 35 | R19: 26 | S19: 10.7 | T19: =S19+1.2 -> 11.9 | U19: =S19*N19 -> 64.2 | V19: =T19*N19 -> 71.4
A20: =C19+1 -> 7 | B20: - | C20: =C19+N20 -> 14 | H20: 60 | M20: =SUM(G20:L20) -> 60 | N20: 8 | O20: =M20*N20 -> 480 | S20: 11.5 | T20: =S20+1.2 -> 12.7 | U20: =S20*N20 -> 92 | V20: =T20*N20 -> 101.6
A21: =C20+1 -> 15 | B21: - | C21: =C20+N21 -> 23 | I21: 50 | M21: =SUM(G21:L21) -> 50 | N21: 9 | O21: =M21*N21 -> 450 | S21: 10.2 | T21: =S21+1.2 -> 11.4 | U21: =S21*N21 -> 91.8 | V21: =T21*N21 -> 102.6
A22: =C21+1 -> 24 | B22: - | C22: =C21+N22 -> 31 | J22: 50 | M22: =SUM(G22:L22) -> 50 | N22: 8 | O22: =M22*N22 -> 400 | S22: 10.9 | T22: =S22+1.2 -> 12.1 | U22: =S22*N22 -> 87.2 | V22: =T22*N22 -> 96.8
A23: =C22+1 -> 32 | B23: - | C23: =C22+N23 -> 37 | K23: 45 | M23: =SUM(G23:L23) -> 45 | N23: 6 | O23: =M23*N23 -> 270 | S23: 9.4 | T23: =S23+1.2 -> 10.6 | U23: =S23*N23 -> 56.4 | V23: =T23*N23 -> 63.6
A24: =C23+1 -> 38 | B24: - | C24: =C23+N24 -> 38 | G24: 48 | M24: =SUM(G24:L24) -> 48 | N24: 1 | O24: =M24*N24 -> 48 | S24: 10 | T24: =S24+1.2 -> 11.2 | U24: =S24*N24 -> 10 | V24: =T24*N24 -> 11.2
A25: =C24+1 -> 39 | B25: - | C25: =C24+N25 -> 39 | H25: 28 | K25: 35 | M25: =SUM(G25:L25) -> 63 | N25: 1 | O25: =M25*N25 -> 63 | S25: 10.7 | T25: =S25+1.2 -> 11.9 | U25: =S25*N25 -> 10.7 | V25: =T25*N25 -> 11.9
A26: =C25+1 -> 40 | B26: - | C26: =C25+N26 -> 40 | I26: 38 | J26: 14 | M26: =SUM(G26:L26) -> 52 | N26: 1 | O26: =M26*N26 -> 52 | S26: 10.2 | T26: =S26+1.2 -> 11.4 | U26: =S26*N26 -> 10.2 | V26: =T26*N26 -> 11.4
A27: TOTAL | G27: =O19+G24 -> 408 | H27: =O20+H25 -> 508 | I27: =O21+I26 -> 488 | J27: =O22+J26 -> 414 | K27: =O23+K25 -> 305 | N27: =SUM(N19:N26) -> 40 | O27: =SUM(O19:O26) -> 2123 | P27: =(P19*Q19*R19)/1000000*N27 -> 2.002 | U27: =SUM(U19:U26) -> 422.5 | V27: =SUM(V19:V26) -> 470.5
A29: GRAND TOTAL | N29: =N27 -> 40 | O29: =O27 -> 2123 | P29: =P27 -> 2.002 | U29: =U27 -> 422.5 | V29: =V27 -> 470.5
A31: ORDER & SHIP QTY | D31: =D17 -> COLOR | G31: =G18 -> S | H31: =H18 -> M | I31: =I18 -> L | J31: =J18 -> XL | K31: =K18 -> XXL | L31: =L18 -> 3XL | M31: TOTAL
A32: ORDER QTY. | D32: =D19 -> Navy | G32: 400 | H32: 500 | I32: 500 | J32: 400 | K32: 300 | M32: =G32+H32+I32+J32+K32+L32 -> 2100
A33: SHIP QTY. | G33: =G27 -> 408 | H33: =H27 -> 508 | I33: =I27 -> 488 | J33: =J27 -> 414 | K33: =K27 -> 305 | M33: =G33+H33+I33+J33+K33+L33 -> 2123

Sheet 107KP
A1: FOUR DESIGN (PVT.) LTD
A2: A 100% Export Oriented Knit Garments
A3: Plot # S - 7 & S - 8, BSCIC, I/E, Fatullah, Narayanganj.
A5: PACKING LIST
A7: BUYER | E7: : | F7: PACIFIC COLLECTIONS | U7: Date:
A8: ORDER NO | E8: : | F8: 53920
A9: ITEM CODE | E9: : | F9: 107KP
A10: ITEM NAME | E10: : | F10: Embroidered Fern
A11: ORDER QTY. | E11: : | F11: 1650
A12: SHIPPEPD QTY. | E12: : | F12: =M31 -> 1694
A13: EXCESS/SHORT QTY. | E13: : | F13: =F12-F11 -> 44
A14: CTN QTY. | E14: : | F14: =N27 -> 33
A15: FABRICATION | E15: : | F15: 100% Cotton, 150 GSM.
A17: CTN NO. | D17: COLOR | G17: SIZE | M17: PCS/CTN | N17: TOTAL CTN | O17: TOTAL QTY | P17: CTN MEAS. | S17: WEIGHT (KGS) | U17: WEIGHT (KGS)
G18: S | H18: M | I18: L | J18: XL | K18: XXL | L18: 3XL | P18: L | Q18: W | R18: H | S18: N.W. | T18: G.W | U18: TTL N.W | V18: TTL G.W
A19: 1 | B19: - | C19: =N19 -> 6 | D19: Black | G19: 60 | M19: =SUM(G19:L19) -> 60 | N19: 6 | O19: =M19*N19 -> 360 | P19: 55 | Q19: 35 | R19: 26 | S19: 9.8 | T19: =S19+1.2 -> 11 | U19: =S19*N19 -> 58.8 | V19: =T19*N19 -> 66
A20: =C19+1 -> 7 | B20: - | C20: =C19+N20 -> 12 | H20: 60 | M20: =SUM(G20:L20) -> 60 | N20: 6 | O20: =M20*N20 -> 360 | S20: 10.45 | T20: =S20+1.2 -> 11.65 | U20: =S20*N20 -> 62.7 | V20: =T20*N20 -> 69.9
A21: =C20+1 -> 13 | B21: - | C21: =C20+N21 -> 18 | I21: 50 | M21: =SUM(G21:L21) -> 50 | N21: 6 | O21: =M21*N21 -> 300 | S21: 9.3 | T21: =S21+1.2 -> 10.5 | U21: =S21*N21 -> 55.8 | V21: =T21*N21 -> 63
A22: =C21+1 -> 19 | B22: - | C22: =C21+N22 -> 26 | J22: 50 | M22: =SUM(G22:L22) -> 50 | N22: 8 | O22: =M22*N22 -> 400 | S22: 10.8 | T22: =S22+1.2 -> 12 | U22: =S22*N22 -> 86.4 | V22: =T22*N22 -> 96
A23: =C22+1 -> 27 | B23: - | C23: =C22+N23 -> 32 | K23: 40 | M23: =SUM(G23:L23) -> 40 | N23: 6 | O23: =M23*N23 -> 240 | S23: 8.1 | T23: =S23+1.2 -> 9.3 | U23: =S23*N23 -> 48.6 | V23: =T23*N23 -> 55.8
